Workbook

Sheet Czech Republic
C1: t - čas | D1: GDP per capita (constant 2015 US$ | E1: population | F1: ln(bazických indexů) | G1: S-S model HDP per capita
A2: 60 | B2: 2005 | C2: 0 | D2: 15147.721 | E2: 14913564 | F2: ln(Lt/L0)=y | G2: l = L0·egt
A3: 61 | B3: 2006 | C3: 1 | D3: 16107.304 | E3: 15220495 | F3: =LN(D3/$D$2) -> 0.061422728 | G3: =$D$2*EXP($C$40*C3) -> 15416.688
A4: 62 | B4: 2007 | C4: 2 | D4: 16892.543 | E4: 15505121 | F4: =LN(D4/$D$2) -> 0.10902215 | G4: =$D$2*EXP($C$40*C4) -> 15690.43
A5: 63 | B5: 2008 | C5: 3 | D5: 17190.647 | E5: 15784817 | F5: =LN(D5/$D$2) -> 0.12651534 | G5: =$D$2*EXP($C$40*C5) -> 15969.032
A6: 64 | B6: 2009 | C6: 4 | D6: 16272.808 | E6: 16075128 | F6: =LN(D6/$D$2) -> 0.071645402 | G6: =$D$2*EXP($C$40*C6) -> 16252.582
A7: 65 | B7: 2010 | C7: 5 | D7: 16665.932 | E7: 16401413 | F7: =LN(D7/$D$2) -> 0.095516502 | G7: =$D$2*EXP($C$40*C7) -> 16541.166
A8: 66 | B8: 2011 | C8: 6 | D8: 16926.285 | E8: 16730895 | F8: =LN(D8/$D$2) -> 0.1110176 | G8: =$D$2*EXP($C$40*C8) -> 16834.874
A9: 67 | B9: 2012 | C9: 7 | D9: 16772.354 | E9: 17042272 | F9: =LN(D9/$D$2) -> 0.10188181 | G9: =$D$2*EXP($C$40*C9) -> 17133.798
A10: 68 | B10: 2013 | C10: 8 | D10: 16759.781 | E10: 17372779 | F10: =LN(D10/$D$2) -> 0.1011319 | G10: =$D$2*EXP($C$40*C10) -> 17438.029
A11: 69 | B11: 2014 | C11: 9 | D11: 17118.043 | E11: 17704538 | F11: =LN(D11/$D$2) -> 0.12228291 | G11: =$D$2*EXP($C$40*C11) -> 17747.663
A12: 70 | B12: 2015 | C12: 10 | D12: 17931.599 | E12: 18029982 | F12: =LN(D12/$D$2) -> 0.16871433 | G12: =$D$2*EXP($C$40*C12) -> 18062.794
A13: 71 | B13: 2016 | C13: 11 | D13: 18359.098 | E13: 18354855 | F13: =LN(D13/$D$2) -> 0.19227512 | G13: =$D$2*EXP($C$40*C13) -> 18383.521
A14: 72 | B14: 2017 | C14: 12 | D14: 19257.693 | E14: 18653146 | F14: =LN(D14/$D$2) -> 0.2400605 | G14: =$D$2*EXP($C$40*C14) -> 18709.942
... A21: 79 | B21: 2024 | C21: 19 | D21: 20444.543 | E21: 20278946 | F21: =LN(D21/$D$2) -> 0.29986588 | G21: =$D$2*EXP($C$40*C21) -> 21163.075
A22: 80
A23: 81 | B23: 摘要輸出
A24: 82
A25: 83 | B25: 迴歸統計
A26: 84 | B26: R 的倍數 | C26: 0.98488547
A27: 85 | B27: R 平方 | C27: 0.96999939
A28: 86 | B28: 調整的 R 平方 | C28: 0.91444383
A29: 87 | B29: 標準誤 | C29: 0.036258877
A30: 88 | B30: 觀察值個數 | C30: 19
A31: 89
A32: 90 | B32: ANOVA
A33: 91 | C33: 自由度 | D33: SS | E33: MS | F33: F | G33: 顯著值
A34: 92 | B34: 迴歸 | C34: 1 | D34: 0.76514293 | E34: 0.76514293 | F34: 581.98781 | G34: 1.369879e-14
A35: 93 | B35: 殘差 | C35: 18 | D35: 0.02366471 | E35: 0.0013147061
A36: 94 | B36: 總和 | C36: 19 | D36: 0.78880764
A37: 95
A38: 96 | C38: 係數 | D38: 標準誤 | E38: t 統計 | F38: P-值 | G38: 下限 95% | H38: 上限 95% | I38: 下限 95.0% | J38: 上限 95.0%
A39: 97 | B39: 截距 | C39: 0 | D39: #N/A | E39: #N/A | F39: #N/A | G39: #N/A | H39: #N/A | I39: #N/A | J39: #N/A
A40: 98 | B40: X 變數 1 | C40: 0.017600411 | D40: 0.00072956815 | E40: 24.124423 | F40: 3.7016106e-15 | G40: 0.016067645 | H40: 0.019133177 | I40: 0.016067645 | J40: 0.019133177
A41: 99
A42: 100
A43: 101
A44: 102 | B44: 殘差輸出
A45: 103
A46: 104 | B46: 觀察值 | C46: Očekávaná Y | D46: Rezidua CZ
...

Sheet Taiwan
C1: t - čas | D1: GDP per capita (constant 2015 US$ | E1: population | F1: ln(bazických indexů) | G1: S-S model HDP per capita
A2: 60 | B2: 2005 | C2: 0 | D2: 16600.116 | E2: 14913564 | F2: ln(Lt/L0)=y | G2: l = L0·egt
A3: 61 | B3: 2006 | C3: 1 | D3: 17485.929 | E3: 15220495 | F3: =LN(D3/$D$2) -> 0.051986851 | G3: =$D$2*EXP($C$40*C3) -> 17150.508
A4: 62 | B4: 2007 | C4: 2 | D4: 18607.105 | E4: 15505121 | F4: =LN(D4/$D$2) -> 0.11413383 | G4: =$D$2*EXP($C$40*C4) -> 17719.15
A5: 63 | B5: 2008 | C5: 3 | D5: 18690.276 | E5: 15784817 | F5: =LN(D5/$D$2) -> 0.11859374 | G5: =$D$2*EXP($C$40*C5) -> 18306.645
A6: 64 | B6: 2009 | C6: 4 | D6: 18324.376 | E6: 16075128 | F6: =LN(D6/$D$2) -> 0.098822532 | G6: =$D$2*EXP($C$40*C6) -> 18913.619
A7: 65 | B7: 2010 | C7: 5 | D7: 20147.16 | E7: 16401413 | F7: =LN(D7/$D$2) -> 0.19365367 | G7: =$D$2*EXP($C$40*C7) -> 19540.718
A8: 66 | B8: 2011 | C8: 6 | D8: 20839.84 | E8: 16730895 | F8: =LN(D8/$D$2) -> 0.22745685 | G8: =$D$2*EXP($C$40*C8) -> 20188.609
A9: 67 | B9: 2012 | C9: 7 | D9: 21232.322 | E9: 17042272 | F9: =LN(D9/$D$2) -> 0.24611497 | G9: =$D$2*EXP($C$40*C9) -> 20857.982
A10: 68 | B10: 2013 | C10: 8 | D10: 21690.286 | E10: 17372779 | F10: =LN(D10/$D$2) -> 0.26745483 | G10: =$D$2*EXP($C$40*C10) -> 21549.548
A11: 69 | B11: 2014 | C11: 9 | D11: 22656.567 | E11: 17704538 | F11: =LN(D11/$D$2) -> 0.31104006 | G11: =$D$2*EXP($C$40*C11) -> 22264.043
A12: 70 | B12: 2015 | C12: 10 | D12: 22930.449 | E12: 18029982 | F12: =LN(D12/$D$2) -> 0.32305599 | G12: =$D$2*EXP($C$40*C12) -> 23002.229
A13: 71 | B13: 2016 | C13: 11 | D13: 23374.064 | E13: 18354855 | F13: =LN(D13/$D$2) -> 0.34221737 | G13: =$D$2*EXP($C$40*C13) -> 23764.89
A14: 72 | B14: 2017 | C14: 12 | D14: 24189.244 | E14: 18653146 | F14: =LN(D14/$D$2) -> 0.37649838 | G14: =$D$2*EXP($C$40*C14) -> 24552.837
... A21: 79 | B21: 2024 | C21: 19 | D21: 31127.849 | E21: 20278946 | F21: =LN(D21/$D$2) -> 0.62869322 | G21: =$D$2*EXP($C$40*C21) -> 30850.545
A22: 80
A23: 81 | B23: 摘要輸出
A24: 82
A25: 83 | B25: 迴歸統計
A26: 84 | B26: R 的倍數 | C26: 0.99822831
A27: 85 | B27: R 平方 | C27: 0.99645975
A28: 86 | B28: 調整的 R 平方 | C28: 0.9409042
A29: 87 | B29: 標準誤 | C29: 0.022774994
A30: 88 | B30: 觀察值個數 | C30: 19
A31: 89
A32: 90 | B32: ANOVA
A33: 91 | C33: 自由度 | D33: SS | E33: MS | F33: F | G33: 顯著值
A34: 92 | B34: 迴歸 | C34: 1 | D34: 2.6279402 | E34: 2.6279402 | F34: 5066.3938 | G34: 1.7277951e-22
A35: 93 | B35: 殘差 | C35: 18 | D35: 0.009336606 | E35: 0.00051870033
A36: 94 | B36: 總和 | C36: 19 | D36: 2.6372768
A37: 95
A38: 96 | C38: 係數 | D38: 標準誤 | E38: t 統計 | F38: P-值 | G38: 下限 95% | H38: 上限 95% | I38: 下限 95.0% | J38: 上限 95.0%
A39: 97 | B39: 截距 | C39: 0 | D39: #N/A | E39: #N/A | F39: #N/A | G39: #N/A | H39: #N/A | I39: #N/A | J39: #N/A
A40: 98 | B40: X 變數 1 | C40: 0.032618145 | D40: 0.00045825772 | E40: 71.178605 | F40: 1.622811e-23 | G40: 0.031655381 | H40: 0.033580909 | I40: 0.031655381 | J40: 0.033580909
A41: 99
A42: 100
A43: 101
A44: 102 | B44: 殘差輸出
A45: 103
A46: 104 | B46: 觀察值 | C46: Očekávaná Y | D46: Rezidua Taiwan 2005-2024
...

Sheet Singapore
C1: t - čas | D1: GDP per capita (constant 2015 US$ | E1: population | F1: ln(bazických indexů) | G1: S-S model HDP per capita
A2: 60 | B2: 2005 | C2: 0 | D2: 41798.488 | E2: 14913564 | F2: ln(Lt/L0)=y | G2: l = L0·egt
A3: 61 | B3: 2006 | C3: 1 | D3: 44159.41 | E3: 15220495 | F3: =LN(D3/$D$2) -> 0.054945877 | G3: =$D$2*EXP($C$40*C3) -> 42963.734
A4: 62 | B4: 2007 | C4: 2 | D4: 46178.814 | E4: 15505121 | F4: =LN(D4/$D$2) -> 0.099660952 | G4: =$D$2*EXP($C$40*C4) -> 44161.463
A5: 63 | B5: 2008 | C5: 3 | D5: 44601.58 | E5: 15784817 | F5: =LN(D5/$D$2) -> 0.064909114 | G5: =$D$2*EXP($C$40*C5) -> 45392.583
A6: 64 | B6: 2009 | C6: 4 | D6: 43331.875 | E6: 16075128 | F6: =LN(D6/$D$2) -> 0.036028331 | G6: =$D$2*EXP($C$40*C6) -> 46658.024
A7: 65 | B7: 2010 | C7: 5 | D7: 48752.052 | E7: 16401413 | F7: =LN(D7/$D$2) -> 0.15388711 | G7: =$D$2*EXP($C$40*C7) -> 47958.742
A8: 66 | B8: 2011 | C8: 6 | D8: 50713.533 | E8: 16730895 | F8: =LN(D8/$D$2) -> 0.19333262 | G8: =$D$2*EXP($C$40*C8) -> 49295.721
A9: 67 | B9: 2012 | C9: 7 | D9: 51679.353 | E9: 17042272 | F9: =LN(D9/$D$2) -> 0.21219817 | G9: =$D$2*EXP($C$40*C9) -> 50669.972
A10: 68 | B10: 2013 | C10: 8 | D10: 53298.973 | E10: 17372779 | F10: =LN(D10/$D$2) -> 0.24305689 | G10: =$D$2*EXP($C$40*C10) -> 52082.534
A11: 69 | B11: 2014 | C11: 9 | D11: 54681.934 | E11: 17704538 | F11: =LN(D11/$D$2) -> 0.26867321 | G11: =$D$2*EXP($C$40*C11) -> 53534.475
A12: 70 | B12: 2015 | C12: 10 | D12: 55645.607 | E12: 18029982 | F12: =LN(D12/$D$2) -> 0.28614296 | G12: =$D$2*EXP($C$40*C12) -> 55026.893
A13: 71 | B13: 2016 | C13: 11 | D13: 56986.785 | E13: 18354855 | F13: =LN(D13/$D$2) -> 0.30995924 | G13: =$D$2*EXP($C$40*C13) -> 56560.916
A14: 72 | B14: 2017 | C14: 12 | D14: 59485.302 | E14: 18653146 | F14: =LN(D14/$D$2) -> 0.35286908 | G14: =$D$2*EXP($C$40*C14) -> 58137.704
... A21: 79 | B21: 2024 | C21: 19 | D21: 67706.834 | E21: 20278946 | F21: =LN(D21/$D$2) -> 0.48232695 | G21: =$D$2*EXP($C$40*C21) -> 70477.09
A22: 80
A23: 108 | B23: 摘要輸出
A24: 109
A25: 110 | B25: 迴歸統計
A26: 111 | B26: R 的倍數 | C26: 0.99425001
A27: 112 | B27: R 平方 | C27: 0.98853308
A28: 113 | B28: 調整的 R 平方 | C28: 0.93297753
B29: 標準誤 | C29: 0.034690648
B30: 觀察值個數 | C30: 19
B32: ANOVA
C33: 自由度 | D33: SS | E33: MS | F33: F | G33: 顯著值
B34: 迴歸 | C34: 1 | D34: 1.8674193 | E34: 1.8674193 | F34: 1551.7331 | G34: 3.794e-18
B35: 殘差 | C35: 18 | D35: 0.021661939 | E35: 0.0012034411
B36: 總和 | C36: 19 | D36: 1.8890813
C38: 係數 | D38: 標準誤 | E38: t 統計 | F38: P-值 | G38: 下限 95% | H38: 上限 95% | I38: 下限 95.0% | J38: 上限 95.0%
B39: 截距 | C39: 0 | D39: #N/A | E39: #N/A | F39: #N/A | G39: #N/A | H39: #N/A | I39: #N/A | J39: #N/A
B40: X 變數 1 | C40: 0.027496186 | D40: 0.00069801369 | E40: 39.392044 | F40: 6.3906946e-19 | G40: 0.026029713 | H40: 0.028962658 | I40: 0.026029713 | J40: 0.028962658
B44: 殘差輸出
B46: 觀察值 | C46: Očekávaná Y | D46: Rezidua Singapore
B47: 1 | C47: 0.027496186
B48: 2 | C48: 0.054992371
B49: 3 | C49: 0.082488557
B50: 4 | C50: 0.10998474
B51: 5 | C51: 0.13748093
B52: 6 | C52: 0.16497711
...

Sheet Taiwan_54years v.s Rezidu
C1: t - čas | D1: GDP per capita constant 2021 NTW$ 連鎖實質值(2021為參考_新臺幣百萬元) | E1: GDP per capita (constant 2015 US$ | F1: population | G1: ln(bazických indexů) | H1: S-S model HDP per capita
A2: 60 | B2: =$C$58+A2 -> 1971 | C2: 0 | D2: 1007047 | E2: =(D2*$C$61*$C$60)/$C$59/F2 -> 2068.3352 | F2: 14913564 | G2: ln(Lt/L0)=y | H2: l = L0·egt
A3: 61 | B3: =$C$58+A3 -> 1972 | C3: 1 | D3: 1146757 | E3: =(D3*$C$61*$C$60)/$C$59/F3 -> 2307.7845 | F3: 15220495 | G3: =LN(E3/$E$2) -> 0.10954393 | H3: =$E$2*EXP($K$55*C3) -> 2191.2582
A4: 62 | B4: =$C$58+A4 -> 1973 | C4: 2 | D4: 1293910 | E4: =(D4*$C$61*$C$60)/$C$59/F4 -> 2556.1217 | F4: 15505121 | G4: =LN(E4/$E$2) -> 0.21174713 | H4: =$E$2*EXP($K$55*C4) -> 2321.4866
A5: 63 | B5: =$C$58+A5 -> 1974 | C5: 3 | D5: 1328393 | E5: =(D5*$C$61*$C$60)/$C$59/F5 -> 2577.7432 | F5: 15784817 | G5: =LN(E5/$E$2) -> 0.22017026 | H5: =$E$2*EXP($K$55*C5) -> 2459.4546
A6: 64 | B6: =$C$58+A6 -> 1975 | C6: 4 | D6: 1410562 | E6: =(D6*$C$61*$C$60)/$C$59/F6 -> 2687.7592 | F6: 16075128 | G6: =LN(E6/$E$2) -> 0.26196382 | H6: =$E$2*EXP($K$55*C6) -> 2605.6222
A7: 65 | B7: =$C$58+A7 -> 1976 | C7: 5 | D7: 1612019 | E7: =(D7*$C$61*$C$60)/$C$59/F7 -> 3010.52 | F7: 16401413 | G7: =LN(E7/$E$2) -> 0.37536879 | H7: =$E$2*EXP($K$55*C7) -> 2760.4766
A8: 66 | B8: =$C$58+A8 -> 1977 | C8: 6 | D8: 1795917 | E8: =(D8*$C$61*$C$60)/$C$59/F8 -> 3287.9084 | F8: 16730895 | G8: =LN(E8/$E$2) -> 0.46350759 | H8: =$E$2*EXP($K$55*C8) -> 2924.5342
A9: 67 | B9: =$C$58+A9 -> 1978 | C9: 7 | D9: 2039378 | E9: =(D9*$C$61*$C$60)/$C$59/F9 -> 3665.4125 | F9: 17042272 | G9: =LN(E9/$E$2) -> 0.57219686 | H9: =$E$2*EXP($K$55*C9) -> 3098.3419
A10: 68 | B10: =$C$58+A10 -> 1979 | C10: 8 | D10: 2219540 | E10: =(D10*$C$61*$C$60)/$C$59/F10 -> 3913.3285 | F10: 17372779 | G10: =LN(E10/$E$2) -> 0.63764426 | H10: =$E$2*EXP($K$55*C10) -> 3282.4791
A11: 69 | B11: =$C$58+A11 -> 1980 | C11: 9 | D11: 2397980 | E11: =(D11*$C$61*$C$60)/$C$59/F11 -> 4148.7148 | F11: 17704538 | G11: =LN(E11/$E$2) -> 0.69605457 | H11: =$E$2*EXP($K$55*C11) -> 3477.5597
A12: 70 | B12: =$C$58+A12 -> 1981 | C12: 10 | D12: 2568255 | E12: =(D12*$C$61*$C$60)/$C$59/F12 -> 4363.1031 | F12: 18029982 | G12: =LN(E12/$E$2) -> 0.74643949 | H12: =$E$2*EXP($K$55*C12) -> 3684.2342
A13: 71 | B13: =$C$58+A13 -> 1982 | C13: 11 | D13: 2691811 | E13: =(D13*$C$61*$C$60)/$C$59/F13 -> 4492.0671 | F13: 18354855 | G13: =LN(E13/$E$2) -> 0.77556893 | H13: =$E$2*EXP($K$55*C13) -> 3903.1915
A14: 72 | B14: =$C$58+A14 -> 1983 | C14: 12 | D14: 2934720 | E14: =(D14*$C$61*$C$60)/$C$59/F14 -> 4819.1141 | F14: 18653146 | G14: =LN(E14/$E$2) -> 0.84584608 | H14: =$E$2*EXP($K$55*C14) -> 4135.1617
... A37: 95 | B37: =$C$58+A37 -> 2006 | C37: 35 | D37: 13029192 | E37: =(D37*$C$61*$C$60)/$C$59/F37 -> 17485.929 | F37: 22823455 | G37: =LN(E37/$E$2) -> 2.1346525 | H37: =$E$2*EXP($K$55*C37) -> 15601.38
A38: 96 | B38: =$C$58+A38 -> 2007 | C38: 36 | D38: 13921703 | E38: =(D38*$C$61*$C$60)/$C$59/F38 -> 18607.105 | F38: 22917444 | G38: =LN(E38/$E$2) -> 2.1967995 | H38: =$E$2*EXP($K$55*C38) -> 16528.583 | J38: 摘要輸出
A39: 97 | B39: =$C$58+A39 -> 2008 | C39: 37 | D39: 14032900 | E39: =(D39*$C$61*$C$60)/$C$59/F39 -> 18690.276 | F39: 22997696 | G39: =LN(E39/$E$2) -> 2.2012594 | H39: =$E$2*EXP($K$55*C39) -> 17510.892
A40: 98 | B40: =$C$58+A40 -> 2009 | C40: 38 | D40: 13806459 | E40: =(D40*$C$61*$C$60)/$C$59/F40 -> 18324.376 | F40: 23078402 | G40: =LN(E40/$E$2) -> 2.1814882 | H40: =$E$2*EXP($K$55*C40) -> 18551.58 | J40: 迴歸統計
A41: 99 | B41: =$C$58+A41 -> 2010 | C41: 39 | D41: 15220971 | E41: =(D41*$C$61*$C$60)/$C$59/F41 -> 20147.16 | F41: 23140948 | G41: =LN(E41/$E$2) -> 2.2763193 | H41: =$E$2*EXP($K$55*C41) -> 19654.117 | J41: R 的倍數 | K41: 0.99405171
A42: 100 | B42: =$C$58+A42 -> 2011 | C42: 40 | D42: 15780050 | E42: =(D42*$C$61*$C$60)/$C$59/F42 -> 20839.84 | F42: 23193518 | G42: =LN(E42/$E$2) -> 2.3101225 | H42: =$E$2*EXP($K$55*C42) -> 20822.178 | J42: R 平方 | K42: 0.9881388
A43: 101 | B43: =$C$58+A43 -> 2012 | C43: 41 | D43: 16130510 | E43: =(D43*$C$61*$C$60)/$C$59/F43 -> 21232.322 | F43: 23270367 | G43: =LN(E43/$E$2) -> 2.3287806 | H43: =$E$2*EXP($K$55*C43) -> 22059.659 | J43: 調整的 R 平方 | K43: 0.96890803
A44: 102 | B44: =$C$58+A44 -> 2013 | C44: 42 | D44: 16531048 | E44: =(D44*$C$61*$C$60)/$C$59/F44 -> 21690.286 | F44: 23344670 | G44: =LN(E44/$E$2) -> 2.3501205 | H44: =$E$2*EXP($K$55*C44) -> 23370.684 | J44: 標準誤 | K44: 0.19816195
A45: 103 | B45: =$C$58+A45 -> 2014 | C45: 43 | D45: 17311105 | E45: =(D45*$C$61*$C$60)/$C$59/F45 -> 22656.567 | F45: 23403635 | G45: =LN(E45/$E$2) -> 2.3937057 | H45: =$E$2*EXP($K$55*C45) -> 24759.624 | J45: 觀察值個數 | K45: 53
A46: 104 | B46: =$C$58+A46 -> 2015 | C46: 44 | D46: 17564746 | E46: =(D46*$C$61*$C$60)/$C$59/F46 -> 22930.449 | F46: 23462914 | G46: =LN(E46/$E$2) -> 2.4057216 | H46: =$E$2*EXP($K$55*C46) -> 26231.111
A47: 105 | B47: =$C$58+A47 -> 2016 | C47: 45 | D47: 17945024 | E47: =(D47*$C$61*$C$60)/$C$59/F47 -> 23374.064 | F47: 23515945 | G47: =LN(E47/$E$2) -> 2.424883 | H47: =$E$2*EXP($K$55*C47) -> 27790.049 | J47: ANOVA
A48: 106 | B48: =$C$58+A48 -> 2017 | C48: 46 | D48: 18602118 | E48: =(D48*$C$61*$C$60)/$C$59/F48 -> 24189.244 | F48: 23555522 | G48: =LN(E48/$E$2) -> 2.459164 | H48: =$E$2*EXP($K$55*C48) -> 29441.636 | K48: 自由度 | L48: SS | M48: MS | N48: F | O48: 顯著值
A49: 107 | B49: =$C$58+A49 -> 2018 | C49: 47 | D49: 19142600 | E49: =(D49*$C$61*$C$60)/$C$59/F49 -> 24866.134 | F49: 23580080 | G49: =LN(E49/$E$2) -> 2.4867628 | H49: =$E$2*EXP($K$55*C49) -> 31191.379 | J49: 迴歸 | K49: 1 | L49: 170.11137 | M49: 170.11137 | N49: 4332.0434 | O49: 5.3238855e-51
A50: 108 | B50: =$C$58+A50 -> 2019 | C50: 48 | D50: 19727465 | E50: =(D50*$C$61*$C$60)/$C$59/F50 -> 25608.552 | F50: 23596027 | G50: =LN(E50/$E$2) -> 2.5161823 | H50: =$E$2*EXP($K$55*C50) -> 33045.11 | J50: 殘差 | K50: 52 | L50: 2.0419443 | M50: 0.03926816
A51: 109 | B51: =$C$58+A51 -> 2020 | C51: 49 | D51: 20402197 | E51: =(D51*$C$61*$C$60)/$C$59/F51 -> 26499.985 | F51: 23582179 | G51: =LN(E51/$E$2) -> 2.5504001 | H51: =$E$2*EXP($K$55*C51) -> 35009.01 | J51: 總和 | K51: 53 | L51: 172.15332
A52: 110 | B52: =$C$58+A52 -> 2021 | C52: 50 | D52: 21773291 | E52: =(D52*$C$61*$C$60)/$C$59/F52 -> 28418.132 | F52: 23468275 | G52: =LN(E52/$E$2) -> 2.6202834 | H52: =$E$2*EXP($K$55*C52) -> 37089.627
A53: 111 | B53: =$C$58+A53 -> 2022 | C53: 51 | D53: 22357584 | E53: =(D53*$C$61*$C$60)/$C$59/F53 -> 29366.31 | F53: 23319977 | G53: =LN(E53/$E$2) -> 2.6531041 | H53: =$E$2*EXP($K$55*C53) -> 39293.897 | K53: 係數 | L53: 標準誤 | M53: t 統計 | N53: P-值 | O53: 下限 95% | P53: 上限 95% | Q53: 下限 95.0% | R53: 上限 95.0%
A54: 112 | B54: =$C$58+A54 -> 2023 | C54: 52 | D54: 22600156 | E54: =(D54*$C$61*$C$60)/$C$59/F54 -> 29656.229 | F54: 23342541 | G54: =LN(E54/$E$2) -> 2.6629282 | H54: =$E$2*EXP($K$55*C54) -> 41629.168 | J54: 截距 | K54: 0 | L54: #N/A | M54: #N/A | N54: #N/A | O54: #N/A | P54: #N/A | Q54: #N/A | R54: #N/A
A55: 113 | B55: =$C$58+A55 -> 2024 | C55: 53 | D55: 23790526 | E55: =(D55*$C$61*$C$60)/$C$59/F55 -> 31127.849 | F55: 23410331 | G55: =LN(E55/$E$2) -> 2.7113589 | H55: =$E$2*EXP($K$55*C55) -> 44103.226 | J55: X 變數 1 | K55: 0.057731866 | L55: 0.00087714057 | M55: 65.81826 | N55: 9.3688474e-52 | O55: 0.055971755 | P55: 0.059491977 | Q55: 0.055971755 | R55: 0.059491977
B58: 西元 | C58: 1911 | G58: 殘差輸出
B59: exchange rate | C59: 31.7 | G59: 觀察值 | H59: Očekávaná Y | I59: Rezidua Taiwan1971-2024
B60: unit change | C60: 1000000 | G60: 1 | H60: 0.057731866 | I60: 0.051812066
B61: Ratio | C61: ='[1]2015 base'!B4/'Taiwan_54years v.s Rezidu'!D46 -> 0.97098358 | G61: 2 | H61: 0.11546373 | I61: 0.096283402
G62: 3 | H62: 0.1731956 | I62: 0.046974663
G63: 4 | H63: 0.23092746 | I63: 0.031036358
G64: 5 | H64: 0.28865933 | I64: 0.086709459
...

Sheet Convergence_4
C1: Korea | D1: Singapore | E1: Czech Republic | F1: Taiwan | G1: směrodatná odchylka | H1: variační koeficient | I1: průměr | L1: Korea | M1: Singapore | N1: Czech Republic | O1: Taiwan | P1: směrodatná odchylka | Q1: variační koeficient | R1: průměr
C2: HDP per capita | L2: ln(HDP per capita)
A3: 0 | B3: 2005 | C3: 21197.199 | D3: 41798.488 | E3: 15147.721 | F3: ='Taiwan_54years v.s Rezidu'!E36 -> 16600.116 | G3: =_xlfn.STDEV.S(C3:F3) -> 12347.312 | H3: =G3/I3 -> 0.52129416 | I3: =AVERAGE(C3:F3) -> 23685.881 | K3: 2005 | L3: =LN(C3) -> 9.9616243 | M3: =LN(D3) -> 10.640615 | N3: =LN(E3) -> 9.6256054 | O3: =LN(F3) -> 9.717165 | P3: =_xlfn.STDEV.S(L3:O3) -> 0.45871991 | Q3: =P3/R3 -> 0.04593514 | R3: =AVERAGE(L3:O3) -> 9.9862525
A4: 1 | B4: 2006 | C4: 22196.208 | D4: 44159.41 | E4: 16107.304 | F4: ='Taiwan_54years v.s Rezidu'!E37 -> 17485.929 | G4: =_xlfn.STDEV.S(C4:F4) -> 13044.602 | H4: =G4/I4 -> 0.52205108 | I4: =AVERAGE(C4:F4) -> 24987.213 | K4: 2006 | L4: =LN(C4) -> 10.007677 | M4: =LN(D4) -> 10.695561 | N4: =LN(E4) -> 9.6870281 | O4: =LN(F4) -> 9.7691518 | P4: =_xlfn.STDEV.S(L4:O4) -> 0.45780391 | Q4: =P4/R4 -> 0.045598659 | R4: =AVERAGE(L4:O4) -> 10.039854
A5: 2 | B5: 2007 | C5: 23365.14 | D5: 46178.814 | E5: 16892.543 | F5: ='Taiwan_54years v.s Rezidu'!E38 -> 18607.105 | G5: =_xlfn.STDEV.S(C5:F5) -> 13557.967 | H5: =G5/I5 -> 0.51627959 | I5: =AVERAGE(C5:F5) -> 26260.901 | K5: 2007 | L5: =LN(C5) -> 10.059 | M5: =LN(D5) -> 10.740276 | N5: =LN(E5) -> 9.7346276 | O5: =LN(F5) -> 9.8312988 | P5: =_xlfn.STDEV.S(L5:O5) -> 0.45351571 | Q5: =P5/R5 -> 0.044941254 | R5: =AVERAGE(L5:O5) -> 10.091301
A6: 3 | B6: 2008 | C6: 23887.06 | D6: 44601.58 | E6: 17190.647 | F6: ='Taiwan_54years v.s Rezidu'!E39 -> 18690.276 | G6: =_xlfn.STDEV.S(C6:F6) -> 12668.674 | H6: =G6/I6 -> 0.48553136 | I6: =AVERAGE(C6:F6) -> 26092.391 | K6: 2008 | L6: =LN(C6) -> 10.081092 | M6: =LN(D6) -> 10.705525 | N6: =LN(E6) -> 9.7521207 | O6: =LN(F6) -> 9.8357587 | P6: =_xlfn.STDEV.S(L6:O6) -> 0.43116058 | Q6: =P6/R6 -> 0.042716132 | R6: =AVERAGE(L6:O6) -> 10.093624
A7: 4 | B7: 2009 | C7: 23952.813 | D7: 43331.875 | E7: 16272.808 | F7: ='Taiwan_54years v.s Rezidu'!E40 -> 18324.376 | G7: =_xlfn.STDEV.S(C7:F7) -> 12342.294 | H7: =G7/I7 -> 0.48457273 | I7: =AVERAGE(C7:F7) -> 25470.468 | K7: 2009 | L7: =LN(C7) -> 10.083841 | M7: =LN(D7) -> 10.676644 | N7: =LN(E7) -> 9.6972508 | O7: =LN(F7) -> 9.8159875 | P7: =_xlfn.STDEV.S(L7:O7) -> 0.43652519 | Q7: =P7/R7 -> 0.043355832 | R7: =AVERAGE(L7:O7) -> 10.068431
A8: 5 | B8: 2010 | C8: 25455.617 | D8: 48752.052 | E8: 16665.932 | F8: ='Taiwan_54years v.s Rezidu'!E41 -> 20147.16 | G8: =_xlfn.STDEV.S(C8:F8) -> 14456.948 | H8: =G8/I8 -> 0.52087366 | I8: =AVERAGE(C8:F8) -> 27755.19 | K8: 2010 | L8: =LN(C8) -> 10.144692 | M8: =LN(D8) -> 10.794503 | N8: =LN(E8) -> 9.7211219 | O8: =LN(F8) -> 9.9108186 | P8: =_xlfn.STDEV.S(L8:O8) -> 0.46774195 | Q8: =P8/R8 -> 0.046115737 | R8: =AVERAGE(L8:O8) -> 10.142784
A9: 6 | B9: 2011 | C9: 26191.644 | D9: 50713.533 | E9: 16926.285 | F9: ='Taiwan_54years v.s Rezidu'!E42 -> 20839.84 | G9: =_xlfn.STDEV.S(C9:F9) -> 15179.875 | H9: =G9/I9 -> 0.52950912 | I9: =AVERAGE(C9:F9) -> 28667.825 | K9: 2011 | L9: =LN(C9) -> 10.173196 | M9: =LN(D9) -> 10.833948 | N9: =LN(E9) -> 9.736623 | O9: =LN(F9) -> 9.9446218 | P9: =_xlfn.STDEV.S(L9:O9) -> 0.47589586 | Q9: =P9/R9 -> 0.04678444 | R9: =AVERAGE(L9:O9) -> 10.172097
A10: 7 | B10: 2012 | C10: 26680.275 | D10: 51679.353 | E10: 16772.354 | F10: ='Taiwan_54years v.s Rezidu'!E43 -> 21232.322 | G10: =_xlfn.STDEV.S(C10:F10) -> 15594.37 | H10: =G10/I10 -> 0.5360534 | I10: =AVERAGE(C10:F10) -> 29091.076 | K10: 2012 | L10: =LN(C10) -> 10.19168 | M10: =LN(D10) -> 10.852814 | N10: =LN(E10) -> 9.7274872 | O10: =LN(F10) -> 9.9632799 | P10: =_xlfn.STDEV.S(L10:O10) -> 0.48459322 | Q10: =P10/R10 -> 0.047584644 | R10: =AVERAGE(L10:O10) -> 10.183815
A11: 8 | B11: 2013 | C11: 27399.616 | D11: 53298.973 | E11: 16759.781 | F11: ='Taiwan_54years v.s Rezidu'!E44 -> 21690.286 | G11: =_xlfn.STDEV.S(C11:F11) -> 16266.301 | H11: =G11/I11 -> 0.54608427 | I11: =AVERAGE(C11:F11) -> 29787.164 | K11: 2013 | L11: =LN(C11) -> 10.218284 | M11: =LN(D11) -> 10.883672 | N11: =LN(E11) -> 9.7267373 | O11: =LN(F11) -> 9.9846198 | P11: =_xlfn.STDEV.S(L11:O11) -> 0.49600541 | Q11: =P11/R11 -> 0.048612118 | R11: =AVERAGE(L11:O11) -> 10.203328
A12: 9 | B12: 2014 | C12: 28100.01 | D12: 54681.934 | E12: 17118.043 | F12: ='Taiwan_54years v.s Rezidu'!E45 -> 22656.567 | G12: =_xlfn.STDEV.S(C12:F12) -> 16643.764 | H12: =G12/I12 -> 0.54321907 | I12: =AVERAGE(C12:F12) -> 30639.138 | K12: 2014 | L12: =LN(C12) -> 10.243525 | M12: =LN(D12) -> 10.909289 | N12: =LN(E12) -> 9.7478883 | O12: =LN(F12) -> 10.028205 | P12: =_xlfn.STDEV.S(L12:O12) -> 0.49489025 | Q12: =P12/R12 -> 0.04836584 | R12: =AVERAGE(L12:O12) -> 10.232227
A13: 10 | B13: 2015 | C13: 28737.439 | D13: 55645.607 | E13: 17931.599 | F13: ='Taiwan_54years v.s Rezidu'!E46 -> 22930.449 | G13: =_xlfn.STDEV.S(C13:F13) -> 16813.074 | H13: =G13/I13 -> 0.5369655 | I13: =AVERAGE(C13:F13) -> 31311.273 | K13: 2015 | L13: =LN(C13) -> 10.265956 | M13: =LN(D13) -> 10.926758 | N13: =LN(E13) -> 9.7943197 | O13: =LN(F13) -> 10.040221 | P13: =_xlfn.STDEV.S(L13:O13) -> 0.48638894 | Q13: =P13/R13 -> 0.047421056 | R13: =AVERAGE(L13:O13) -> 10.256814
A14: 11 | B14: 2016 | C14: 29467.124 | D14: 56986.785 | E14: 18359.098 | F14: ='Taiwan_54years v.s Rezidu'!E47 -> 23374.064 | G14: =_xlfn.STDEV.S(C14:F14) -> 17235.884 | H14: =G14/I14 -> 0.53783534 | I14: =AVERAGE(C14:F14) -> 32046.768 | K14: 2016 | L14: =LN(C14) -> 10.29103 | M14: =LN(D14) -> 10.950575 | N14: =LN(E14) -> 9.8178805 | O14: =LN(F14) -> 10.059382 | P14: =_xlfn.STDEV.S(L14:O14) -> 0.48717496 | Q14: =P14/R14 -> 0.047391865 | R14: =AVERAGE(L14:O14) -> 10.279717
... A21: 18 | B21: 2023 | C21: 34121.021 | D21: 66167.36 | E21: 20251.749 | F21: ='Taiwan_54years v.s Rezidu'!E54 -> 29656.229 | G21: =_xlfn.STDEV.S(C21:F21) -> 19935.331 | H21: =G21/I21 -> 0.53091383 | I21: =AVERAGE(C21:F21) -> 37549.09 | K21: 2023 | L21: =LN(C21) -> 10.437669 | M21: =LN(D21) -> 11.099943 | N21: =LN(E21) -> 9.9159964 | O21: =LN(F21) -> 10.297427 | P21: =_xlfn.STDEV.S(L21:O21) -> 0.49342889 | Q21: =P21/R21 -> 0.047273452 | R21: =AVERAGE(L21:O21) -> 10.437759
A22: 19 | B22: 2024 | C22: =C21*1.022 -> 34871.684 | D22: 67706.834 | E22: 20444.543 | F22: ='Taiwan_54years v.s Rezidu'!E55 -> 31127.849 | G22: =_xlfn.STDEV.S(C22:F22) -> 20384.195 | H22: =G22/I22 -> 0.52894129 | I22: =AVERAGE(C22:F22) -> 38537.727 | K22: 2024 | L22: =LN(C22) -> 10.45943 | M22: =LN(D22) -> 11.122942 | N22: =LN(E22) -> 9.9254713 | O22: =LN(F22) -> 10.345858 | P22: =_xlfn.STDEV.S(L22:O22) -> 0.4960495 | Q22: =P22/R22 -> 0.047407944 | R22: =AVERAGE(L22:O22) -> 10.463426
A23: x | B23: ln(y0) | C23: =LN(C3) -> 9.9616243 | D23: =LN(D3) -> 10.640615 | E23: =LN(E3) -> 9.6256054 | F23: =LN(F3) -> 9.717165
A24: y | B24: g=(Yt/Yo)/t-1 | C24: =LN(C22/C3)/$A$22 -> 0.02620032 | D24: =LN(D22/D3)/$A$22 -> 0.025385629 | E24: =LN(E22/E3)/$A$22 -> 0.015782415 | F24: =LN(F22/F3)/$A$22 -> 0.033089117
A50: 摘要輸出
A52: 迴歸統計
A53: R 的倍數 | B53: 0.97174239
A54: R 平方 | B54: 0.94428326
A55: 調整的 R 平方 | B55: -1.3333333
A56: 標準誤 | B56: 0.0070482748
A57: 觀察值個數 | B57: 1
A59: ANOVA
B60: 自由度 | C60: SS | D60: MS | E60: F | F60: 顯著值
A61: 迴歸 | B61: 4 | C61: 0.0025258267 | D61: 0.00063145667 | E61: 50.843787 | F61: #NUM!
A62: 殘差 | B62: 3 | C62: 0.00014903453 | D62: 4.9678178e-05
A63: 總和 | B63: 7 | C63: 0.0026748612
B65: 係數 | C65: 標準誤 | D65: t 統計 | E65: P-值 | F65: 下限 95% | G65: 上限 95% | H65: 下限 95.0% | I65: 上限 95.0%
A66: 截距 | H66: 0 | I66: 0
A67: X 變數 1 | H67: 0 | I67: 0
A68: X 變數 2 | H68: 0 | I68: 0
A69: X 變數 3 | B69: 0 | C69: #N/A | D69: 0 | E69: 1 | F69: 0 | G69: 0 | H69: 0 | I69: 0
A70: X 變數 4 | B70: 0.0025143508 | C70: 0.00035261998 | D70: 7.1304829 | E70: 0.0056778991 | F70: 0.0013921566 | G70: 0.0036365449 | H70: 0.0013921566 | I70: 0.0036365449
A74: 殘差輸出
A76: 觀察值 | B76: 預測 Y | C76: 殘差
A77: 1 | B77: 0.024432361 | C77: 0.0017679593

Sheet SS_3
Q4: Country | R4: Czech Rep. | S4: Singapore | T4: Taiwan
Q5: 2005 GDP per capita | R5: 15147.721 | S5: 16600.116 | T5: 41798.488
Q6: SS模型 方程式 | R6: y = 15148e0.0176x | S6: y = 41798e0.0275x | T6: y = 16600e0.0326x
Q7: g 科技成長 (e指數) | R7: 0.0176 | S7: 0.0275 | T7: 0.0326
Q8: SS模型 R² | R8: R² = 0.969 | S8: R² = 0.988 | T8: R² = 0.996
Q9: 二次式 方程式 | R9: $y = 6.93t^2 + 135.52t + 16021.58$ | S9: $y = 1.08t^2 + 1419.83t + 41509.49$ | T9: $y = 18.17t^2 + 362.72t + 17468.81$
Q10: 二次式 R² | R10: 0.8851 | S10: 0.9539 | T10: 0.9896
