Workbook

Sheet úvodní stránka
A1: Strategický management
A2: Semestrální práce
A9: ZS 2024/2025
A12: Jména a příjmení členů týmu
A16: Velikost zvolené organizace (zaměstnanci nebo tržby) | B16: Celkový počet zaměstnanců 72
A17: Hlavní obor činnosti organizace (slovy co jí živí, ne CZ-NACE) | B17: Nobilis Tilia, s.r.o. Je výroba přírodní kosmeticky založené na aromaterapii, i požádá vzdělávací kurzy.

Sheet 1. obecné prostředí
A1: ZÁKLADNÍ PŘEDSTAVENÍ ORGANIZACE A ANALÝZA OBECNÉHO PROSTŘEDÍ
A3: Pro zpracování odpovědí využijte aktuální, relevantní a hodnověrné informační zdroje, jejichž seznam uveďte pod vaše odpovědi. V textu odkazujte na použité zdroje, použití zdrojů je součástí hodnocení.
A5: Charakterizujte misi vaší organizace.
A6: Pokud je má organizace veřejně deklarované, posuďte jejich vhodnost. Pokud nemá pak navrhněte.
A7: "Vnášíme krásu a harmonii do života našich zákazníků i místa, kde působíme" [1] Tento popis, není explicitně vyhlásen za misi. Je na webové strance firmy. Navržená mise: S profesionálními, nadšenými a důvěryhodnými kolegy vnášíme krásu a harmonii do života našich zákazníků i místa, kde působíme. Firma prostřenictvím služby s láskou prodavá produkty. Výroby produktů, neustálý vývoj nových produktů a způsoby dodávání zákazníkům – to vše vyžaduje zaměstnance s těmito kvalitami.
A8: Charakterizujte operační prostor organizace.
A9: Věcně, prostorově, časově.
A10: Firma vznkla v roce 2004. Hlavním předmětem podnikání firmy je výroba přirodní kosmetiky založené na aromaterapii. Firma také pořádá vzdělávací kurzy. Produkty včetně přižozeného esenciálního oleje, péče o pleť, online i offline kurzy jsou věšinou zaměřené na ženy. Některé jsou zaměřené na muže a děti. Firma má B2B eshop, i kamennou prodejnu(4).Vytvořila prodejní síť prostřednictvím obchodních zástupců. Ve Vlčí Hoře je Centrum aromaterapie, kamenná prodejna, bylinková čajovna i rozlehlá zahrada. [2]
A11: Zdůvodněte závěry PEST analýzy a s použitím metody přístupu MAP diskutujte nejzávažnější výsledky.
A12: Které z částí PEST analýzy jsou pro vaši organizaci příležitostí/hrozbou a případně které naopak nepředstavují významnou změnotvornou sílu a PROČ?
A13: Balení výrobků a materiálů v obalech je pečlivě sledováno legistlativou EU. Cílem je snížit odpad z obalů a podpořit recyklované obaly jako jsou bio-based obalové materiály a bio-based biodegradable plastic.[3] Firma má dlouhodobou tradici dbá na to, aby podnikala ekologicky šetrně i na to, aby respektovala své okolí. Příležitosti i hrozba: i když firma se s tím už postupně vyrovnává, kvůli výsokým požádavkům na přírodní kosmetiku bez konzervantů výužívá nemálý počet nizkých recyklovavých plastiků, jako jsou PET, HDPE... Ekonomické faktory, které společnost během covidu ovlivňovaly, se postupně zlepšovaly a inflace zůstala stabilní několik měsíců.[5] [6]. Data ukazují, že se očekává růst kupní síly a obnova reálných příjmů v roce 2024 [7]. Pandemie nabízí příležitost prozkoumat potenciál esenciálních olejů. Po covidu se zvýšil zájem o výrobky, které posilují imunitu a podporují zdraví.[8] Aromaterapeutické produkty se tak těší zvýšené poptávce, což je pro firmu příležitost k růstu.
A14: Seznam využitých informačních zdrojů
... A22: 8. COVID-19 pandemic sheds a new research spotlight on antiviral potential of essential oils - A bibliometric study https://www-webofscience-com.zdroje.vse.cz/wos/alldb/full-record/WOS:001056240300001

Sheet 2. odvětví
A1: ANALÝZA ODVĚTVÍ A KONKURENČNÍHO PROSTŘEDÍ
A3: Pro zpracování odpovědí využijte aktuální, relevantní a hodnověrné informační zdroje, jejichž seznam uveďte pod vaše odpovědi. V textu odkazujte na použité zdroje, použití zdrojů je součástí hodnocení.
A5: Působí v daném odvětví globalizační trendy? Které globalizačních trendů (metoda 4C) podporují nebo brzdí globalizaci?
A6: Jaké lze v odvětví očekávat změny působením globalizačních trendů na úrovni Customers, Country, Competition, Costs?
A7: The growing usage of aromatherapy for numerous health-related benefits is the most important factor expected to drive market growth[1]. In the Skin Care Market, revenue is expected to show an annual growth rate of 9.04% worldwide in 5 years[2][3][4].The rapid rise of the e-commerce is also expected to cushion market growth. 4C analysis: Customers: marketing applies to different regions. However, culturally differences still exist due to, e.g different preferences for flavors and herbs. Country: Legal differences are the key. Products are categorized in marketing as cosmetics, natural health products, or as medicines with varying degrees of stringency, which may create barriers to entry for globalization. Competition: In addition to major players, there are also many small regional companies, creating regional independent brands with a stress on sustainability. Cost: Economies of scale have their benefits, as they require significant capital investment in research and acquisition of essential oils.
A8: Vyhodnoťte důležitost jednotlivých sil dle Porterova modelu pěti sil z hlediska vlivu na vaši organizaci.
A9: S pomocí přístupu MAP definujte HLAVNÍ HROZBY pro budoucí působení organizace
A10: Nově vstupující: velká síla z důvodu atraktivního růstu odvětví. Ale malá síla, protože odvětví nemá nízké fixní náklady se získáváním určitých kvalitních organických éterických produktů a certifikátů. Proto je stále atraktivní pro nové vstupující, ale je méně pravděpodobné, že nově vstupující vstoupí ve velkém počtu. Dodavatelé: malá síla, díky širokému portfoliu. V případě výpadku suroviny, může být nabídnut jiný produkt. [5] Odběratelé: trh je vyspělý, zákazníci mají mnoho možnosti, i dominantní postavení. Zařadí se tak do velké síly. Substituty: alternativní medicína by byla substitutem, ale ještě není univerzální.[6][7] Konkurenční prostředí: v ČR existují velké firmy, ale zádný dominantní konkurent.[8] [9]Fixní náklady jsou vysoké kvůli komplexním surovinám a zařízením. MAP: Hlavní hráči budou ochotnější investovat a přilákat nové spotřebitele cenou nebo inovacemi. S šířením informací na internetu, důrazem lidí na zdraví a na globalizaci je výběr firmy ze strany zákazníků stále snazší.
A11: Naznačte POMOCÍ OBRÁZKU hodnotové křivky pro nejvýznamnější KONKURENČNÍ PRODUKTY a porovnejte je s předpokládaným PŘÁNÍM ZÁKAZNÍKŮ.
A12: Vidíte prostor pro uplatnění strategie modrého oceánu? Diskutujte nejvýznamnější atributy produktu.
A13: Bylo navrženo celkem 11 důležitých atributů produktu. Na základě výše uvedených výsledků analýzy jsou zřejmé následující předpoklady: Konkurentem je největší mezinárodní značka. Může přilákat spotřebitele nejlepší kvalitou, nejlepším účinkem, kompletní produktovou řadou a známostí značky. I když je cena vyšší, může realizovat úspory vzhledem k rozsahu. Předpokládejme, že zákazníci jsou lokální zákazníci (Čechy a Slovensko) a pozvedneme na vyšší úroveň to, co současná konkurence ještě neudělala např. dostupnost, specifický vkus a členství založené na loajalitě. To bude náš modrý oceán. Překonáme očekávání zákazníků, vytvoříme regionální diferenciaci a zvýšíme přilnavost a loajalitu zákazníků. Aby se snížily výrobní náklady, lze odvrhnout faktory, jako je balení a selektivita.
A14: #VALUE!
A15: Seznam využitých informačních zdrojů
A16: 1. https://www.marketresearchfuture.com/reports/essential-oil-aromatherapy-market-3319
A17: 2.https://www.statista.com/outlook/emo/beauty-personal-care/skin-care/worldwide#sales-channels
A18: 3.https://www.statista.com/outlook/emo/beauty-personal-care/skin-care/europe
A19: 4.https://www.statista.com/outlook/emo/beauty-personal-care/skin-care/czechia
A20: 5.výroční zpráva [2022] https://or.justice.cz/ias/ui/vypis-sl-detail?dokument=77507582&subjektId=33499&spis=560095
A21: 6.https://www.denik.cz/zdravi/alternativni-medicina-2020.html
A22: 7.https://vesmir.cz/cz/casopis/archiv-casopisu/2018/cislo-11/alternativni-medicina-diskuse-kruhu.html
A23: 8.MANUFAKTURA s.r.o. účetní závěrka [2022] https://or.justice.cz/ias/ui/vypis-sl-detail?dokument=78837827&subjektId=869332&spis=1243617
A24: 9.Botanicus, spol. s r.o. účetní závěrka [2023], výroční zpráva [2023] https://or.justice.cz/ias/ui/vypis-sl-detail?dokument=82627747&subjektId=442576&spis=98862

Sheet 3. interní
A1: ANALÝZA INTERNÍHO PROSTŘEDÍ
A3: Pro zpracování odpovědí využijte aktuální, relevantní a hodnověrné informační zdroje, jejichž seznam uveďte pod vaše odpovědi. V textu odkazujte na použité zdroje, použití zdrojů je součástí hodnocení.
A5: Zhodnoťte význam zdrojů pro předmět činnosti organizace a porovnejte reálný stav s optimálním.
A6: S pomocí přístupu MAP definujte SILNÉ A SLABÉ STRÁNKY pro působení organizace.
A7: Zdroje: Suroviny, prvotřídní přírodní suroviny s ověřeným původem, efektivní výrobní prostory. Certifikace, pověst značky, distribuční systém. Jedinečný systém školení, System duplikujícího se otevření nových prodejen. MAP: Firma má stabilní systém s řízením dodavatelů a výrobou esenciálních olejů. 3 příslušné certificatce a 3 prodejny v ČR kromě hlavního centra obchodu. Příjmy z prodeje jsou další zdroje prostřednictvím online a distributorů. 1. Certifikace jsou tuzemské vysoce kvalitní bio certifikace, chybí však certifikace od velkých mezinárodních institucí, jako je IFRA[1], což ztěžuje získání důvěry zákazníků, kteří mají vyšší požadavky na produkty. 2. Vůně a čich jsou nejdůležitější podstatou produktu. Sice existuje dostupný online shop, v průběhu expanzní podnikaní jsou ale kamenné obchody nepostradatelné. Ve srovnání s konkurencí je počet prodejen stále velmi malý. 3. Jedinečný systém školení, nejen vytvoří hodnotu pro zákazníka, ale také pro organizaci.
A8: Sestavte Porterův hodnotový řetězec pro vaši organizaci (vložte OBRÁZEK).
A9: Nesnažte se rozdělit vaši organizaci přesně dle Porterova diagramu, ale sestavte diagram optimálně vystihující vaší organizaci.
A11: Zhodnoťte nastavení procesů ve vaší organizaci s pomocí výše uvedeného hodnotového řetězce.
A12: Porovnejte náklady generované jednotlivými částmi organizace a jimi vytvořenou hodnotu pro ZÁKAZNÍKA nebo ORGANIZACI.
A13: Většina organizací má podobné procesy od vstupu přes výstup až po prodej. Tato společnost používá produkty pro dvojí použití, nejen konkretní produkty, ale také přeměnu produktů na znalostní kurzy k prodeji. Tento obchodní model vyžaduje vynikající lidské zdroje. Z dlouhodobého hlediska se vytváří důvěryhodnost produktu a značka, což vytváří hodnotu pro zákazníky a organizaci prostřednictvím přenosu znalostí. [2]
A14: Pomocí VRIO analýzy vyhodnoťte zdroje a vztahy, jimiž disponuje Vaše organizace (TABULKA + komentář).
A15: Přináší nějaký zdroj organizaci konkurenční dočasnou nebo trvalou konkurenční výhodu? Zdůvodněte.
... A21: 4.https://manufaktura.cz/prodejny/

Sheet 4. stakeholdeři a změna
A1: ANALÝZA INTERNÍHO PROSTŘEDÍ
A3: Pro zpracování odpovědí využijte aktuální, relevantní a hodnověrné informační zdroje, jejichž seznam uveďte pod vaše odpovědi. V textu odkazujte na použité zdroje, použití zdrojů je součástí hodnocení.
A5: Stakeholdery a jejich profily zakreslete do POWER – INTEREST matrix (vložte OBRÁZEK).
A6: K hodnocení moci a zájmu využijte 10-ti bodovou škálu, díky které zanesete stakeholdery do kvadrantů. Pomocí různých druhů čar zaneste vazby mezi stakeholdery.
A7: #VALUE!
A8: Zařaďte 2 jednotlivé stakeholdery dle Socio-dynamického přístupu.
A9: Jednoznačně zdůvodněte, jak se tito stakeholdeři dle tohoto přístupu chovají a diskutujte s vazbami zakreslenými v POWER – INTEREST matrix.
A10: Celebrity branding mají velký vliv na fanoušky. Nejsou jako influenceři, kteři by měly tendencí k negativnímu, celebrity musí být lojální, jejích osobní porvěst úzce souvisí s firmou. Image obou stránek se úzce vzajemně ovlivnují. Na matrixu představují výsoký zájem. Pokud jde o sílu, celebrity branding hraje roli stejně tak jako partnerské prodejny. U nich záleží na tom, jestli výrobky firmy dokažou přilakát spotřebitele. Proaktiní podpora se ale může stát passivem, když nevytvoří odbyt.
A11: Jak dynamické z hlediska četnosti a hloubky inovací je prostředí, v němž operuje vaše organizace?
A12: Diskutujte historickou četnost a hloubku inovací v odvětví i očekávaný další vývoj.
A13: V posledních letech se na trhu objevuje čím dál více přírodní a bio kosmetiky. Ale užívání slov „přírodní“ a „bio“ v tomto průmyslu není zatím zákony nijak omezeno[3][4]. Víc a víc organizací se zabývají standardy and regulacemi. Je jisté, že tento trend vede k innovaci odvětví. Vzhledem k ochraně přírodního prostřední exotic Eos jsou vyráběny ze vzácných materiálů[5]. Innovace vyžaduje různorodé znalosti. jako jsou technologie, věda, botanikza[6]... To může vest k inkrementalní inovaci.
A14: Navrhněte INKREMENTÁLNÍ nebo SKOKOVOU inovaci pro Vaši organizaci. Vyberte s ohledm na vhodnost.
A15: Vysvětlete, v které oblasti a proč očekáváte možnost úspěchu. Pokud prostor pro žádnou inovaci nevidíte, tak zdůvodněte.
A16: #VALUE!
A17: Seznam využitých informačních zdrojů
A18: 1.ČOI: Česká obchodní inspekce. Available online: https://www.coi.cz/o-coi/pusobnost-uradu/
A19: 2. výroční zpráva [2020] Available online: https://or.justice.cz/ias/ui/vypis-sl-firma?subjektId=33499
A20: 3. Co znamená certifikovaná přírodní kosmetika.Available online: https://blog.nobilis.cz/co-znamena-certifikovana-prirodni-kosmetika/
A21: 4. NATURAL COSMETICS CERTIFICATIONS & EU COSMETIC LABELLING REGULATIONS.Available online: https://taobe.consulting/natural-and-bio-cosmetics/
A22: 5. EUROPEAN HUB ON NEW CHALLENGES IN THE FIELD OF ESSENTIAL OILS (EOHUB). A PROPOSAL FOR UNIVERSITY-INDUSTRY COOPERATION.Available online:
A23: https://www-webofscience-com.zdroje.vse.cz/wos/woscc/full-record/WOS:000530109205069
A24: 6.System analysis and design of aromatherapy products for innovation performance assessment toward competitive commercialization phase.Available online:
A25: https://www-webofscience-com.zdroje.vse.cz/wos/woscc/full-record/WOS:000621585400042

Sheet 5. Faktory prostředí
A1: Poznámky k faktorům
A2: Název faktoru | B2: Komentář - MAP přístup (Monitor, Analyse, Predict) | C2: Zařazení | D2: Kód | F2: kód | M2: Silná stránka
A3: Prospěch ze zdravotního povědomí | B3: Po covidu se zvýšil zájem o výrobky, které posilují imunitu a podporují zdraví. Aromaterapeutické produkty se tak těší zvýšené poptávce. Naše firma v tom odvětví a vyrobkoý sortment má dobrou pověst. Firma tak očekává lepší příjem než v minulosti. | C3: Silná stránka | D3: =IF(C3="Slabá stránka","W",IF(C3="Silná stránka","S",IF(C3="Příležitost","O","T"))) -> S | E3: =IF(C3="Slabá stránka",COUNTIF(C3,"Slabá stránka"),IF(C3="Silná stránka",COUNTIF(C3,"Silná stránka"),IF(C3="Příležitost",COUNTIF(C3,"Příležitost"),COUNTIF(C3,"Hrozba")))) -> 1 | F3: =_xlfn.CONCAT(D3,E3) -> S1 | M3: Slabá stránka
A4: Ekologicy založená firma | B4: Firma má dlouhodobou tradici a dbá na to, aby podnikala ekologicky. To přispívá k pozitivnímu vnímání značky, což může zvyšovat loajalitu zákazníků. Umožní to rozšíření trhu díky preferenci ekologicky orientovaných zákazníků. | C4: Silná stránka | D4: =IF(C4="Slabá stránka","W",IF(C4="Silná stránka","S",IF(C4="Příležitost","O","T"))) -> S | E4: =IF(C4="Slabá stránka",COUNTIF(C3:C4,"Slabá stránka"),IF(C4="Silná stránka",COUNTIF(C3:C4,"Silná stránka"),IF(C4="Příležitost",COUNTIF(C3:C4,"Příležitost"),COUNTIF(C3:C4,"Hrozba")))) -> 2 | F4: =_xlfn.CONCAT(D4,E4) -> S2 | M4: Příležitost
A5: Schopnost rychlé reakce na legislativu | B5: Vlastní schopnost rychlé reakce na měnící se legislativu o udržitelném rozvoji. Umožňuje minimalizovat právní a finanční rizika. Firma může podpory využít EU v rámci dotačních programů na udržitelný rozvoj. | C5: Silná stránka | D5: =IF(C5="Slabá stránka","W",IF(C5="Silná stránka","S",IF(C5="Příležitost","O","T"))) -> S | E5: =IF(C5="Slabá stránka",COUNTIF(C$3:C5,"Slabá stránka"),IF(C5="Silná stránka",COUNTIF(C$3:C5,"Silná stránka"),IF(C5="Příležitost",COUNTIF(C$3:C5,"Příležitost"),COUNTIF(C$3:C5,"Hrozba")))) -> 3 | F5: =_xlfn.CONCAT(D5,E5) -> S3 | M5: Hrozba
A6: Přísné pravidla o UR | B6: Balení výrobků a materiálů v obalech je pečlivě sledováno legistlativou EU ohledně SDGs. Firma čelí čím dál přísnějším požadavkům ekologických pravidel. Adaptace na pravidla může být nákladná. | C6: Hrozba | D6: =IF(C6="Slabá stránka","W",IF(C6="Silná stránka","S",IF(C6="Příležitost","O","T"))) -> T | E6: =IF(C6="Slabá stránka",COUNTIF(C$3:C6,"Slabá stránka"),IF(C6="Silná stránka",COUNTIF(C$3:C6,"Silná stránka"),IF(C6="Příležitost",COUNTIF(C$3:C6,"Příležitost"),COUNTIF(C$3:C6,"Hrozba")))) -> 1 | F6: =_xlfn.CONCAT(D6,E6) -> T1
A7: Jednotným marketingovým přístupem lze přílákat nové zákaznky. | B7: Firma má kompletní sortiment zasádních výrobků, což lze použít jednotný přístup z hlediska marketingu k produktům osobní péče. Kvalitní image firmy dokaže přilákat nové zákazniky. | C7: Silná stránka | D7: =IF(C7="Slabá stránka","W",IF(C7="Silná stránka","S",IF(C7="Příležitost","O","T"))) -> S | E7: =IF(C7="Slabá stránka",COUNTIF(C$3:C7,"Slabá stránka"),IF(C7="Silná stránka",COUNTIF(C$3:C7,"Silná stránka"),IF(C7="Příležitost",COUNTIF(C$3:C7,"Příležitost"),COUNTIF(C$3:C7,"Hrozba")))) -> 4 | F7: =_xlfn.CONCAT(D7,E7) -> S4
A8: Překážky pro vstup globalizace | B8: Produkty jsou kategorizovány jako kosmetika, přírodní produkty pro zdraví nebo jako léky s různou mírou přísnosti, což může vytvářet překážky a komplikace pro vstup globalizace. | C8: Hrozba | D8: =IF(C8="Slabá stránka","W",IF(C8="Silná stránka","S",IF(C8="Příležitost","O","T"))) -> T | E8: =IF(C8="Slabá stránka",COUNTIF(C$3:C8,"Slabá stránka"),IF(C8="Silná stránka",COUNTIF(C$3:C8,"Silná stránka"),IF(C8="Příležitost",COUNTIF(C$3:C8,"Příležitost"),COUNTIF(C$3:C8,"Hrozba")))) -> 2 | F8: =_xlfn.CONCAT(D8,E8) -> T2
A9: Konkurence ze strany malých firem | B9: Existuje víc a víc malých regionálních firem, které taky kladou důraz na přirodní biokosmetiky. Ty se možná stanou konkurenty. Je potřeba se odlišovat od svých konkurentů. | C9: Hrozba | D9: =IF(C9="Slabá stránka","W",IF(C9="Silná stránka","S",IF(C9="Příležitost","O","T"))) -> T | E9: =IF(C9="Slabá stránka",COUNTIF(C$3:C9,"Slabá stránka"),IF(C9="Silná stránka",COUNTIF(C$3:C9,"Silná stránka"),IF(C9="Příležitost",COUNTIF(C$3:C9,"Příležitost"),COUNTIF(C$3:C9,"Hrozba")))) -> 3 | F9: =_xlfn.CONCAT(D9,E9) -> T3
A10: Konkurence z innovace mezinárodních velých firem | B10: Úspory z rozsahu velkých mezinárodního firem přispivá k jejích rychlosti výzkumu a vyvoje nových produktů. Naše firma by těžko dohnala innovační dochopnost velkých firem. | C10: Hrozba | D10: =IF(C10="Slabá stránka","W",IF(C10="Silná stránka","S",IF(C10="Příležitost","O","T"))) -> T | E10: =IF(C10="Slabá stránka",COUNTIF(C$3:C10,"Slabá stránka"),IF(C10="Silná stránka",COUNTIF(C$3:C10,"Silná stránka"),IF(C10="Příležitost",COUNTIF(C$3:C10,"Příležitost"),COUNTIF(C$3:C10,"Hrozba")))) -> 4 | F10: =_xlfn.CONCAT(D10,E10) -> T4
A11: Existují silní konkurenti s větším počtem prodejen | B11: Na trhu existují silní konkurenti s větším počtem prodejen a lepší dostupností. I když jejich produkty jsou meně ryzí, jsou těžko rozlišovány zákazníky. Firma by mohla využít své kvalitní zaměření jako klíčovou odlišnost. Může přitáhnout věrnou zákaznickou základnu v konkurenčním prostředí | C11: Hrozba | D11: =IF(C11="Slabá stránka","W",IF(C11="Silná stránka","S",IF(C11="Příležitost","O","T"))) -> T | E11: =IF(C11="Slabá stránka",COUNTIF(C$3:C11,"Slabá stránka"),IF(C11="Silná stránka",COUNTIF(C$3:C11,"Silná stránka"),IF(C11="Příležitost",COUNTIF(C$3:C11,"Příležitost"),COUNTIF(C$3:C11,"Hrozba")))) -> 5 | F11: =_xlfn.CONCAT(D11,E11) -> T5
A12: Ryzí a kvalitnější produkty | B12: Firma má zcela ryzí a kvalitnější produkty vyrobené z esenciálních olejů, proto by společnost měla marketovým segmentem předefinovat cenové umístění, např. u produktů jež nabízí salony v hotelích. | C12: Silná stránka | D12: =IF(C12="Slabá stránka","W",IF(C12="Silná stránka","S",IF(C12="Příležitost","O","T"))) -> S | E12: =IF(C12="Slabá stránka",COUNTIF(C$3:C12,"Slabá stránka"),IF(C12="Silná stránka",COUNTIF(C$3:C12,"Silná stránka"),IF(C12="Příležitost",COUNTIF(C$3:C12,"Příležitost"),COUNTIF(C$3:C12,"Hrozba")))) -> 5 | F12: =_xlfn.CONCAT(D12,E12) -> S5
A13: Nové velké vstupující nedokážou vstoupit rychle | B13: Nové velké firmy vstupující na trh nedokážou vstoupit rychle kvůli nenízkým nákladům a požadavkům na kvalitních organické produkty a ns certifikáty. Je dočasná výhoda, že by mohla odrazovat nové konkutenty. Firma musí investovat do udržení a posilování své značky, aby si udržela náskok před novými konkurenty. | C13: Příležitost | D13: =IF(C13="Slabá stránka","W",IF(C13="Silná stránka","S",IF(C13="Příležitost","O","T"))) -> O | E13: =IF(C13="Slabá stránka",COUNTIF(C$3:C13,"Slabá stránka"),IF(C13="Silná stránka",COUNTIF(C$3:C13,"Silná stránka"),IF(C13="Příležitost",COUNTIF(C$3:C13,"Příležitost"),COUNTIF(C$3:C13,"Hrozba")))) -> 1 | F13: =_xlfn.CONCAT(D13,E13) -> O1
A14: Rostoucí atraktivita odvětví přiláká nové hráče | B14: Rostoucí atraktivita odvětví pravděpodobně přiláká nové hráče, zejména ty, kteří budou schopni zvládnout vysoké počáteční náklady. Můsí využit technologii a inovaci, aby co nejdříve rozšířila své výhody. | C14: Hrozba | D14: =IF(C14="Slabá stránka","W",IF(C14="Silná stránka","S",IF(C14="Příležitost","O","T"))) -> T | E14: =IF(C14="Slabá stránka",COUNTIF(C$3:C14,"Slabá stránka"),IF(C14="Silná stránka",COUNTIF(C$3:C14,"Silná stránka"),IF(C14="Příležitost",COUNTIF(C$3:C14,"Příležitost"),COUNTIF(C$3:C14,"Hrozba")))) -> 6 | F14: =_xlfn.CONCAT(D14,E14) -> T6
A15: Schopnost řízení dodávek | B15: Díky širokému portfoliu v případě výpadku suroviny, může být nabídnut jiný produkt. A proto nebude ohrožená dodavateli. Naopak Firma může vyjednávat lepší ceny nebo podmínky dodávek. A proto dokaže získat víc flexibility na náklady, stavnovení cen nebo marže. | C15: Silná stránka | D15: =IF(C15="Slabá stránka","W",IF(C15="Silná stránka","S",IF(C15="Příležitost","O","T"))) -> S | E15: =IF(C15="Slabá stránka",COUNTIF(C$3:C15,"Slabá stránka"),IF(C15="Silná stránka",COUNTIF(C$3:C15,"Silná stránka"),IF(C15="Příležitost",COUNTIF(C$3:C15,"Příležitost"),COUNTIF(C$3:C15,"Hrozba")))) -> 6 | F15: =_xlfn.CONCAT(D15,E15) -> S6
A16: Může oslovit populaci se zájimem o alternativní medicínu | B16: Alternativní medicína by byla substitutem aromaterapeutických produktů, ale ještě není univerzální v Česku. Vzeldem k tomu firma má dočastnou vyhodu, že může oslovit segmeční zákazníky se zájimem o alternativní medicínu. | C16: Příležitost | D16: =IF(C16="Slabá stránka","W",IF(C16="Silná stránka","S",IF(C16="Příležitost","O","T"))) -> O | E16: =IF(C16="Slabá stránka",COUNTIF(C$3:C16,"Slabá stránka"),IF(C16="Silná stránka",COUNTIF(C$3:C16,"Silná stránka"),IF(C16="Příležitost",COUNTIF(C$3:C16,"Příležitost"),COUNTIF(C$3:C16,"Hrozba")))) -> 2 | F16: =_xlfn.CONCAT(D16,E16) -> O2
A17: Konkurence cenou | B17: Hlavní hráči budou ochotni investovat a přilákat nové spotřebitele cenou. S šířením informací na internetu, důrazem lidí na zdraví a na globalizaci je výběr firmy ze strany zákazníků stále snazší. Firma by mohla ztratit zákazniky, kteři jsou ceňově citliví. | C17: Slabá stránka | D17: =IF(C17="Slabá stránka","W",IF(C17="Silná stránka","S",IF(C17="Příležitost","O","T"))) -> W | E17: =IF(C17="Slabá stránka",COUNTIF(C$3:C17,"Slabá stránka"),IF(C17="Silná stránka",COUNTIF(C$3:C17,"Silná stránka"),IF(C17="Příležitost",COUNTIF(C$3:C17,"Příležitost"),COUNTIF(C$3:C17,"Hrozba")))) -> 1 | F17: =_xlfn.CONCAT(D17,E17) -> W1
... A28: Získání zdroje z EU | B28: Firma získala dotaci z programu OP PIK na přestavbu centra aromaterapie a zahrady. To zajistilo větší výrobní, expediční i skladovací prostory. Zkušenosti a pověst sehnali externí zdroje budou příspivat k budoucí vývoj. Zejména získá zdroje z EU pro projekt innovace udržitelého rozvoje | C28: Příležitost | D28: =IF(C28="Slabá stránka","W",IF(C28="Silná stránka","S",IF(C28="Příležitost","O","T"))) -> O | E28: =IF(C28="Slabá stránka",COUNTIF(C$3:C28,"Slabá stránka"),IF(C28="Silná stránka",COUNTIF(C$3:C28,"Silná stránka"),IF(C28="Příležitost",COUNTIF(C$3:C28,"Příležitost"),COUNTIF(C$3:C28,"Hrozba")))) -> 4 | F28: =_xlfn.CONCAT(D28,E28) -> O4
D29: =IF(C29="Slabá stránka","W",IF(C29="Silná stránka","S",IF(C29="Příležitost","O","T"))) -> T | E29: =IF(C29="Slabá stránka",COUNTIF(C$3:C29,"Slabá stránka"),IF(C29="Silná stránka",COUNTIF(C$3:C29,"Silná stránka"),IF(C29="Příležitost",COUNTIF(C$3:C29,"Příležitost"),COUNTIF(C$3:C29,"Hrozba")))) -> 8 | F29: =_xlfn.CONCAT(D29,E29) -> T8
D30: =IF(C30="Slabá stránka","W",IF(C30="Silná stránka","S",IF(C30="Příležitost","O","T"))) -> T | E30: =IF(C30="Slabá stránka",COUNTIF(C$3:C30,"Slabá stránka"),IF(C30="Silná stránka",COUNTIF(C$3:C30,"Silná stránka"),IF(C30="Příležitost",COUNTIF(C$3:C30,"Příležitost"),COUNTIF(C$3:C30,"Hrozba")))) -> 8 | F30: =_xlfn.CONCAT(D30,E30) -> T8
D31: =IF(C31="Slabá stránka","W",IF(C31="Silná stránka","S",IF(C31="Příležitost","O","T"))) -> T | E31: =IF(C31="Slabá stránka",COUNTIF(C$3:C31,"Slabá stránka"),IF(C31="Silná stránka",COUNTIF(C$3:C31,"Silná stránka"),IF(C31="Příležitost",COUNTIF(C$3:C31,"Příležitost"),COUNTIF(C$3:C31,"Hrozba")))) -> 8 | F31: =_xlfn.CONCAT(D31,E31) -> T8
D32: =IF(C32="Slabá stránka","W",IF(C32="Silná stránka","S",IF(C32="Příležitost","O","T"))) -> T | E32: =IF(C32="Slabá stránka",COUNTIF(C$3:C32,"Slabá stránka"),IF(C32="Silná stránka",COUNTIF(C$3:C32,"Silná stránka"),IF(C32="Příležitost",COUNTIF(C$3:C32,"Příležitost"),COUNTIF(C$3:C32,"Hrozba")))) -> 8 | F32: =_xlfn.CONCAT(D32,E32) -> T8
D33: =IF(C33="Slabá stránka","W",IF(C33="Silná stránka","S",IF(C33="Příležitost","O","T"))) -> T | E33: =IF(C33="Slabá stránka",COUNTIF(C$3:C33,"Slabá stránka"),IF(C33="Silná stránka",COUNTIF(C$3:C33,"Silná stránka"),IF(C33="Příležitost",COUNTIF(C$3:C33,"Příležitost"),COUNTIF(C$3:C33,"Hrozba")))) -> 8 | F33: =_xlfn.CONCAT(D33,E33) -> T8
D34: =IF(C34="Slabá stránka","W",IF(C34="Silná stránka","S",IF(C34="Příležitost","O","T"))) -> T | E34: =IF(C34="Slabá stránka",COUNTIF(C$3:C34,"Slabá stránka"),IF(C34="Silná stránka",COUNTIF(C$3:C34,"Silná stránka"),IF(C34="Příležitost",COUNTIF(C$3:C34,"Příležitost"),COUNTIF(C$3:C34,"Hrozba")))) -> 8 | F34: =_xlfn.CONCAT(D34,E34) -> T8
D35: =IF(C35="Slabá stránka","W",IF(C35="Silná stránka","S",IF(C35="Příležitost","O","T"))) -> T | E35: =IF(C35="Slabá stránka",COUNTIF(C$3:C35,"Slabá stránka"),IF(C35="Silná stránka",COUNTIF(C$3:C35,"Silná stránka"),IF(C35="Příležitost",COUNTIF(C$3:C35,"Příležitost"),COUNTIF(C$3:C35,"Hrozba")))) -> 8 | F35: =_xlfn.CONCAT(D35,E35) -> T8
D36: =IF(C36="Slabá stránka","W",IF(C36="Silná stránka","S",IF(C36="Příležitost","O","T"))) -> T | E36: =IF(C36="Slabá stránka",COUNTIF(C$3:C36,"Slabá stránka"),IF(C36="Silná stránka",COUNTIF(C$3:C36,"Silná stránka"),IF(C36="Příležitost",COUNTIF(C$3:C36,"Příležitost"),COUNTIF(C$3:C36,"Hrozba")))) -> 8 | F36: =_xlfn.CONCAT(D36,E36) -> T8
D37: =IF(C37="Slabá stránka","W",IF(C37="Silná stránka","S",IF(C37="Příležitost","O","T"))) -> T | E37: =IF(C37="Slabá stránka",COUNTIF(C$3:C37,"Slabá stránka"),IF(C37="Silná stránka",COUNTIF(C$3:C37,"Silná stránka"),IF(C37="Příležitost",COUNTIF(C$3:C37,"Příležitost"),COUNTIF(C$3:C37,"Hrozba")))) -> 8 | F37: =_xlfn.CONCAT(D37,E37) -> T8
D38: =IF(C38="Slabá stránka","W",IF(C38="Silná stránka","S",IF(C38="Příležitost","O","T"))) -> T | E38: =IF(C38="Slabá stránka",COUNTIF(C$3:C38,"Slabá stránka"),IF(C38="Silná stránka",COUNTIF(C$3:C38,"Silná stránka"),IF(C38="Příležitost",COUNTIF(C$3:C38,"Příležitost"),COUNTIF(C$3:C38,"Hrozba")))) -> 8 | F38: =_xlfn.CONCAT(D38,E38) -> T8
D39: =IF(C39="Slabá stránka","W",IF(C39="Silná stránka","S",IF(C39="Příležitost","O","T"))) -> T | E39: =IF(C39="Slabá stránka",COUNTIF(C$3:C39,"Slabá stránka"),IF(C39="Silná stránka",COUNTIF(C$3:C39,"Silná stránka"),IF(C39="Příležitost",COUNTIF(C$3:C39,"Příležitost"),COUNTIF(C$3:C39,"Hrozba")))) -> 8 | F39: =_xlfn.CONCAT(D39,E39) -> T8
D40: =IF(C40="Slabá stránka","W",IF(C40="Silná stránka","S",IF(C40="Příležitost","O","T"))) -> T | E40: =IF(C40="Slabá stránka",COUNTIF(C$3:C40,"Slabá stránka"),IF(C40="Silná stránka",COUNTIF(C$3:C40,"Silná stránka"),IF(C40="Příležitost",COUNTIF(C$3:C40,"Příležitost"),COUNTIF(C$3:C40,"Hrozba")))) -> 8 | F40: =_xlfn.CONCAT(D40,E40) -> T8

Sheet 5. SWOT
A3: Silné stránky | C3: váhy | D3: body | E3: vážené skóre | F3: Slabé stránky | H3: váhy | I3: body | J3: vážené skóre | L3: součet váhy | M3: =SUM(C4:C13)+SUM(H4:H13) -> 1 | N3: Vážené skóre interní prostředí | O3: =SUM(E4:E13) + SUM(J4:J13) -> 3.17 | P3: Výsledný kvadrant | Q3: =IF(O3>=2.5,"S","W") -> S
A4: S1 | B4: =VLOOKUP(A4,List2!B$1:C$38,2,FALSE) -> Prospěch ze zdravotního povědomí | C4: 0.04 | D4: 3 | E4: =C4*D4 -> 0.12 | F4: W1 | G4: =VLOOKUP(F4,List2!B$1:C$38,2,FALSE) -> Konkurence cenou | H4: 0.1 | I4: 2 | J4: =H4*I4 -> 0.2
A5: S2 | B5: =VLOOKUP(A5,List2!B$1:C$38,2,FALSE) -> Ekologicy založená firma | C5: 0.05 | D5: 4 | E5: =C5*D5 -> 0.2 | F5: W2 | G5: =VLOOKUP(F5,List2!B$1:C$38,2,FALSE) -> Omezené kamenné prodejny | H5: 0.11 | I5: 2 | J5: =H5*I5 -> 0.22
A6: S3 | B6: =VLOOKUP(A6,List2!B$1:C$38,2,FALSE) -> Schopnost rychlé reakce na legislativu | C6: 0.03 | D6: 3 | E6: =C6*D6 -> 0.09 | F6: W3 | G6: =VLOOKUP(F6,List2!B$1:C$38,2,FALSE) -> Chybí mezinárodní certifikace | H6: 0.03 | I6: 1 | J6: =H6*I6 -> 0.03
A7: S4 | B7: =VLOOKUP(A7,List2!B$1:C$38,2,FALSE) -> Jednotným marketingovým přístupem lze přílákat nové zákaznky. | C7: 0.03 | D7: 3 | E7: =C7*D7 -> 0.09 | F7: W4 | G7: =VLOOKUP(F7,List2!B$1:C$38,2,FALSE) -> Řízení partnerství | H7: 0.11 | I7: 2 | J7: =H7*I7 -> 0.22
A8: S5 | B8: =VLOOKUP(A8,List2!B$1:C$38,2,FALSE) -> Ryzí a kvalitnější produkty | C8: 0.08 | D8: 4 | E8: =C8*D8 -> 0.32 | F8: W5 | G8: =VLOOKUP(F8,List2!B$1:C$38,2,FALSE) -> #N/A | J8: =H8*I8 -> 0
A9: S6 | B9: =VLOOKUP(A9,List2!B$1:C$38,2,FALSE) -> Schopnost řízení dodávek | C9: 0.08 | D9: 4 | E9: =C9*D9 -> 0.32 | F9: W6 | G9: =VLOOKUP(F9,List2!B$1:C$38,2,FALSE) -> #N/A | J9: =H9*I9 -> 0
A10: S7 | B10: =VLOOKUP(A10,List2!B$1:C$38,2,FALSE) -> Jedinečný systém školení | C10: 0.08 | D10: 4 | E10: =C10*D10 -> 0.32 | F10: W7 | G10: =VLOOKUP(F10,List2!B$1:C$38,2,FALSE) -> #N/A | J10: =H10*I10 -> 0
A11: S8 | B11: =VLOOKUP(A11,List2!B$1:C$38,2,FALSE) -> Vysoká kvalita zaměstnamců | C11: 0.08 | D11: 4 | E11: =C11*D11 -> 0.32 | F11: W8 | G11: =VLOOKUP(F11,List2!B$1:C$38,2,FALSE) -> #N/A | J11: =H11*I11 -> 0
A12: S9 | B12: =VLOOKUP(A12,List2!B$1:C$38,2,FALSE) -> Dobře fungující e-shop | C12: 0.1 | D12: 4 | E12: =C12*D12 -> 0.4 | F12: W9 | G12: =VLOOKUP(F12,List2!B$1:C$38,2,FALSE) -> #N/A | J12: =H12*I12 -> 0
A13: S10 | B13: =VLOOKUP(A13,List2!B$1:C$38,2,FALSE) -> Důraz na kvalitní tuzemské bio certifikace | C13: 0.08 | D13: 4 | E13: =C13*D13 -> 0.32 | F13: W10 | G13: =VLOOKUP(F13,List2!B$1:C$38,2,FALSE) -> #N/A | J13: =H13*I13 -> 0
A14: Příležitosti | C14: váhy | D14: body | E14: vážené skóre | F14: Hrozby | H14: váhy | I14: body | J14: vážené skóre | L14: součet váhy | M14: =SUM(C15:C26)+SUM(H15:H26) -> 1 | N14: Vážené skóre externí prostředí | O14: =SUM(E15:E24) + SUM(J15:J24) -> 2.19 | P14: Výsledný kvadrant | Q14: =IF(O14>=2.5,"O","T") -> T
A15: O1 | B15: =VLOOKUP(A15,List2!B$1:C$38,2,FALSE) -> Nové velké vstupující nedokážou vstoupit rychle | C15: 0.04 | D15: 3 | E15: =C15*D15 -> 0.12 | F15: T1 | G15: =VLOOKUP(F15,List2!B$1:C$38,2,FALSE) -> Přísné pravidla o UR | H15: 0.06 | I15: 1 | J15: =H15*I15 -> 0.06
A16: O2 | B16: =VLOOKUP(A16,List2!B$1:C$38,2,FALSE) -> Může oslovit populaci se zájimem o alternativní medicínu | C16: 0.08 | D16: 3 | E16: =C16*D16 -> 0.24 | F16: T2 | G16: =VLOOKUP(F16,List2!B$1:C$38,2,FALSE) -> Překážky pro vstup globalizace | H16: 0.07 | I16: 1 | J16: =H16*I16 -> 0.07
A17: O3 | B17: =VLOOKUP(A17,List2!B$1:C$38,2,FALSE) -> Zavedení více standardů a regulací slov „přírodní“ a „bio“ | C17: 0.08 | D17: 4 | E17: =C17*D17 -> 0.32 | F17: T3 | G17: =VLOOKUP(F17,List2!B$1:C$38,2,FALSE) -> Konkurence ze strany malých firem | H17: 0.08 | I17: 1 | J17: =H17*I17 -> 0.08
A18: O4 | B18: =VLOOKUP(A18,List2!B$1:C$38,2,FALSE) -> Získání zdroje z EU | C18: 0.1 | D18: 4 | E18: =C18*D18 -> 0.4 | F18: T4 | G18: =VLOOKUP(F18,List2!B$1:C$38,2,FALSE) -> Konkurence z innovace mezinárodních velých firem | H18: 0.11 | I18: 2 | J18: =H18*I18 -> 0.22
A19: O5 | B19: =VLOOKUP(A19,List2!B$1:C$38,2,FALSE) -> #N/A | E19: =C19*D19 -> 0 | F19: T5 | G19: =VLOOKUP(F19,List2!B$1:C$38,2,FALSE) -> Existují silní konkurenti s větším počtem prodejen | H19: 0.11 | I19: 2 | J19: =H19*I19 -> 0.22
A20: O6 | B20: =VLOOKUP(A20,List2!B$1:C$38,2,FALSE) -> #N/A | E20: =C20*D20 -> 0 | F20: T6 | G20: =VLOOKUP(F20,List2!B$1:C$38,2,FALSE) -> Rostoucí atraktivita odvětví přiláká nové hráče | H20: 0.09 | I20: 2 | J20: =H20*I20 -> 0.18
A21: O7 | B21: =VLOOKUP(A21,List2!B$1:C$38,2,FALSE) -> #N/A | E21: =C21*D21 -> 0 | F21: T7 | G21: =VLOOKUP(F21,List2!B$1:C$38,2,FALSE) -> Firma by ztratila svou odlišnost kvůli zavedení standardů | H21: 0.08 | I21: 1 | J21: =H21*I21 -> 0.08
A22: O8 | B22: =VLOOKUP(A22,List2!B$1:C$38,2,FALSE) -> #N/A | E22: =C22*D22 -> 0 | F22: T8 | G22: =VLOOKUP(F22,List2!B$1:C$38,2,FALSE) -> Vysoká vyjednávací síla zákazníků | H22: 0.1 | I22: 2 | J22: =H22*I22 -> 0.2
A23: O9 | B23: =VLOOKUP(A23,List2!B$1:C$38,2,FALSE) -> #N/A | E23: =C23*D23 -> 0 | F23: T9 | G23: =VLOOKUP(F23,List2!B$1:C$38,2,FALSE) -> #N/A | J23: =H23*I23 -> 0
A24: O10 | B24: =VLOOKUP(A24,List2!B$1:C$38,2,FALSE) -> #N/A | E24: =C24*D24 -> 0 | F24: T10 | G24: =VLOOKUP(F24,List2!B$1:C$38,2,FALSE) -> #N/A | J24: =H24*I24 -> 0

Sheet 5. TOWS matrix
A1: TOWS MATRIX | D1: Příležitosti | G1: Hrozby
D2: O1 | E2: =VLOOKUP(D2,List2!B$1:C$38,2,FALSE) -> Nové velké vstupující nedokážou vstoupit rychle | G2: T1 | H2: =VLOOKUP(G2,List2!B$1:C$38,2,FALSE) -> Přísné pravidla o UR
D3: O2 | E3: =VLOOKUP(D3,List2!B$1:C$38,2,FALSE) -> Může oslovit populaci se zájimem o alternativní medicínu | G3: T2 | H3: =VLOOKUP(G3,List2!B$1:C$38,2,FALSE) -> Překážky pro vstup globalizace
D4: O3 | E4: =VLOOKUP(D4,List2!B$1:C$38,2,FALSE) -> Zavedení více standardů a regulací slov „přírodní“ a „bio“ | G4: T3 | H4: =VLOOKUP(G4,List2!B$1:C$38,2,FALSE) -> Konkurence ze strany malých firem
D5: O4 | E5: =VLOOKUP(D5,List2!B$1:C$38,2,FALSE) -> Získání zdroje z EU | G5: T4 | H5: =VLOOKUP(G5,List2!B$1:C$38,2,FALSE) -> Konkurence z innovace mezinárodních velých firem
D6: O5 | E6: =VLOOKUP(D6,List2!B$1:C$38,2,FALSE) -> #N/A | G6: T5 | H6: =VLOOKUP(G6,List2!B$1:C$38,2,FALSE) -> Existují silní konkurenti s větším počtem prodejen
A7: Prioritní strategie | D7: O6 | E7: =VLOOKUP(D7,List2!B$1:C$38,2,FALSE) -> #N/A | G7: T6 | H7: =VLOOKUP(G7,List2!B$1:C$38,2,FALSE) -> Rostoucí atraktivita odvětví přiláká nové hráče
D8: O7 | E8: =VLOOKUP(D8,List2!B$1:C$38,2,FALSE) -> #N/A | G8: T7 | H8: =VLOOKUP(G8,List2!B$1:C$38,2,FALSE) -> Firma by ztratila svou odlišnost kvůli zavedení standardů
A9: ='5. SWOT'!Q3 -> S | B9: ='5. SWOT'!Q14 -> T | D9: O8 | E9: =VLOOKUP(D9,List2!B$1:C$38,2,FALSE) -> #N/A | G9: T8 | H9: =VLOOKUP(G9,List2!B$1:C$38,2,FALSE) -> Vysoká vyjednávací síla zákazníků
D10: O9 | E10: =VLOOKUP(D10,List2!B$1:C$38,2,FALSE) -> #N/A | G10: T9 | H10: =VLOOKUP(G10,List2!B$1:C$38,2,FALSE) -> #N/A
D11: O10 | E11: =VLOOKUP(D11,List2!B$1:C$38,2,FALSE) -> #N/A | G11: T10 | H11: =VLOOKUP(G11,List2!B$1:C$38,2,FALSE) -> #N/A
A12: Silné stránky | B12: S1 | C12: =VLOOKUP(B12,List2!B$1:C$38,2,FALSE) -> Prospěch ze zdravotního povědomí | D12: SO strategie | G12: ST strategie
B13: S2 | C13: =VLOOKUP(B13,List2!B$1:C$38,2,FALSE) -> Ekologicy založená firma | D13: SO1 | E13: Zacílení na prémiový trh vzhledem k partnerům | F13: S1,S5,S6,S8,S10,O2,O3 | G13: ST1 | H13: Zvýšení viditelnosti a důvěryhodnosti značky | I13: S2,S5,S10,T3,T4,T5
B14: S3 | C14: =VLOOKUP(B14,List2!B$1:C$38,2,FALSE) -> Schopnost rychlé reakce na legislativu | D14: SO2 | E14: Jako kompletní ekologická firma | F14: S2,O3,O4 | G14: ST2 | H14: Udělejte z partnerů naše mluvčí | I14: S7,T7
B15: S4 | C15: =VLOOKUP(B15,List2!B$1:C$38,2,FALSE) -> Jednotným marketingovým přístupem lze přílákat nové zákaznky. | D15: SO3 | E15: Rozšíření tržního podílu z nových zákazniků | F15: S4,S5.S9, O1,O2 | G15: ST3 | H15: Diferenciace produktů pomocí zaměstnanecké inovace | I15: S8,T7
B16: S5 | C16: =VLOOKUP(B16,List2!B$1:C$38,2,FALSE) -> Ryzí a kvalitnější produkty | D16: SO4 | E16: Zvýšit prodej luxusní produktové sortiment | F16: S1,S5,S10,O2,O3 | G16: ST4
B17: S6 | C17: =VLOOKUP(B17,List2!B$1:C$38,2,FALSE) -> Schopnost řízení dodávek | D17: SO5 | G17: ST5
B18: S7 | C18: =VLOOKUP(B18,List2!B$1:C$38,2,FALSE) -> Jedinečný systém školení | D18: SO6 | G18: ST6
B19: S8 | C19: =VLOOKUP(B19,List2!B$1:C$38,2,FALSE) -> Vysoká kvalita zaměstnamců | D19: SO7 | G19: ST7
B20: S9 | C20: =VLOOKUP(B20,List2!B$1:C$38,2,FALSE) -> Dobře fungující e-shop | D20: SO8 | G20: ST8
B21: S10 | C21: =VLOOKUP(B21,List2!B$1:C$38,2,FALSE) -> Důraz na kvalitní tuzemské bio certifikace | D21: SO9 | G21: ST9
A22: Slabé stránky | B22: W1 | C22: =VLOOKUP(B22,List2!B$1:C$38,2,FALSE) -> Konkurence cenou | D22: WO strategie | G22: WT strategie
B23: W2 | C23: =VLOOKUP(B23,List2!B$1:C$38,2,FALSE) -> Omezené kamenné prodejny | D23: WO1 | E23: Rozšíření kamenných prodejen | F23: W2.O1 | G23: WT1 | H23: Rozšíření tržní podíl ze stabilní sítě prodejních partnerů | I23: W4,T3,T5
B24: W3 | C24: =VLOOKUP(B24,List2!B$1:C$38,2,FALSE) -> Chybí mezinárodní certifikace | D24: WO2 | E24: Formulace průmyslových standardů pro „přírodní“ a „bio“ produkty | F24: W3,O3 | G24: WT2
B25: W4 | C25: =VLOOKUP(B25,List2!B$1:C$38,2,FALSE) -> Řízení partnerství | D25: WO3 | G25: WT3
B26: W5 | C26: =VLOOKUP(B26,List2!B$1:C$38,2,FALSE) -> #N/A | D26: WO4 | G26: WT4
B27: W6 | C27: =VLOOKUP(B27,List2!B$1:C$38,2,FALSE) -> #N/A | D27: WO5 | G27: WT5
B28: W7 | C28: =VLOOKUP(B28,List2!B$1:C$38,2,FALSE) -> #N/A | D28: WO6 | G28: WT6
B29: W8 | C29: =VLOOKUP(B29,List2!B$1:C$38,2,FALSE) -> #N/A | D29: WO7 | G29: WT7
B30: W9 | C30: =VLOOKUP(B30,List2!B$1:C$38,2,FALSE) -> #N/A | D30: WO8 | G30: WT8
B31: W10 | C31: =VLOOKUP(B31,List2!B$1:C$38,2,FALSE) -> #N/A | D31: WO9 | G31: WT9

Sheet 5. cíle - SMART
A1: Kód cíle | B1: Faktory | C1: Název cíle | D1: Priorita cíle | E1: Specific | F1: Measurable | G1: Achievable(interal) | H1: Realistic/Relevant | I1: Time-bound | J1: Dílčí cíle (kód) | K1: Návazné cíle (kód)
A2: SO1 | B2: ='5. TOWS matrix'!F13 -> S1,S5,S6,S8,S10,O2,O3 | C2: Získat nové partnery v prémiovém segmentu | D2: 4 | E2: Navázat spolupráci s hotely a wellness centry, kde budou produkty nabízeny jako součást služeb | F2: Získat spolupráci minimálně 10 hotelů a wellness centrů. Zvýšit příjmy z luxusní segmentů o 20 % do konce roku 2025. | G2: Využít svou výhodu a povest z celebrity | H2: Alokovat 8 % z ročního rozpočtu na motivování sytém pro zástupce v prémiové sortimentu. | I2: do 2026.12 | J2: ST1,SO4
A3: SO2 | B3: ='5. TOWS matrix'!F14 -> S2,O3,O4 | C3: ='5. TOWS matrix'!E14 -> Jako kompletní ekologická firma | D3: 10 | E3: Zvýšit produkty s ekologickým balením. | F3: Zvýšit podíl jedinečných produktů o 20 % z celých produkových SKU. | G3: Pomocí tvurčích zaměstnanců | H3: Využit dotace a zdroje z EU (OP PIK program). | I3: do 2025.12 | J3: ST3
A4: SO3 | B4: ='5. TOWS matrix'!F15 -> S4,S5.S9, O1,O2 | C4: Zvýšit tržní podíl nových zákazníků | D4: 6 | E4: Navýšit počet nových zákazníků. Dosažení bude sledováno na základě dat z prodejů a registrací zákazníků přes e-shop a partnery. | F4: Dosáhnout přírůstku zákazníků o 3 000 do polovinu 2025 a dalších 7 000 do prosince 2025. | G4: Zvyšit viditelnost firmy pomocí rozšíření síť kamenných prodejen na klíčových trzích, marketingových kampanech, a získání nové partnerů v prémiovém segmentu. | H4: Což zvýšení brand awareness taky podpora expanze | I4: do 2026.6 | J4: SO1,ST1, WO1
A5: SO4 | B5: ='5. TOWS matrix'!F13 -> S1,S5,S6,S8,S10,O2,O3 | C5: Zvýšit prodej luxusní produktové sortiment | D5: 5 | E5: Rozšířit nabídku luxusní sortiment o 10 nových produktů zaměřených na špičkové zákazniky. | F5: Zvýšit příjmy z luxusních sortimentů o 15 % do konce roku 2025. | G5: Využít aktuální výrobní kapacity a schopnost řízení dodávek. | H5: Investovat 5 % ročního obratu do vývoje nových produktů a marketingu pro tuto produktovou řadu | I5: do 2025.12 | K5: SO1
A6: WO1 | B6: ='5. TOWS matrix'!F23 -> W2.O1 | C6: Rozšířit síť kamenných prodejen na klíčových trzích | D6: 2 | E6: Otevřít nové kamenné prodejny v obchodních centrech s velikosti 30-50 metrů čtverečních v klíčových regionech zaměřených na interakci se zákazníky | F6: Minmálně otevřit 5 nových kamenných prodejen. Zvýšit počet přímých zákazníků v kamenných prodejnách o 20 % oproti roku 2024 | G6: Díky vysoké kvalitě zaměstnamců, může využije existující know-how a osvědčené procesy řízení. | H6: Použít 10 % ročního zisku na náklady spojené s výstavbou a provozem prodejen | I6: do 2026.12
A7: ST1 | B7: ='5. TOWS matrix'!I13 -> S2,S5,S10,T3,T4,T5 | C7: Zvýšit povědomí o značce firmy prostřednictvím cílených marketingových kampaní | D7: 1 | E7: Spustit 5 cílených marketingových kampaní zaměřených na ekologické a přírodní hodnoty značky. | F7: Zvýšit tržní podíl o 10 % a zvýšit počet sledujících na sociálních sítích o 30 %. | G7: Společnost má vlastní krásnou aromaterapeutickou zahradu, kde lze natáčet přesvědčivé reklamy | H7: Investovat 7 % marketingového rozpočtu do kampaní zaměřených na online a offline propagaci. | I7: do 2025.12 | K7: SO1,SO3,WT1
A8: WT1 | B8: ='5. TOWS matrix'!I23 -> W4,T3,T5 | C8: ='5. TOWS matrix'!H23 -> Rozšíření tržní podíl ze stabilní sítě prodejních partnerů | D8: 3 | E8: Identifikovat nové partnery a zvýšit počet dostupných produktů mezi stávajícími partnery. | F8: Navázat spolupráci s 20 novými partnery a zvýšit dostupnost produktů o minimálně 10 % ze stávajících partnerů. | G8: Aby dosáhl tento cíl, musí najmout 3 obchodní zástupce a navrhovat motivační bonus systém. | H8: Je klíčem k růstu tržeb a posílení značky, tím k budování dlouhodobé stability. | I8: do 2026.12 | J8: ST2
A9: ='5. TOWS matrix'!G14 -> ST2 | B9: ='5. TOWS matrix'!I14 -> S7,T7 | C9: Implementovat jednotný školící program zaměřený na ekologické hodnoty a kvalitu produktů pro všechny současné a nové prodejní partnery | D9: 7 | E9: Vytvořit školící program pro zaměstnance partnerů, který zahrnuje znalosti o produktech, jejich ekologických výhodách a jedinečných vlastnostech. | F9: Proškolit 100 % současných a nových partnerů (minimálně 50 subjektů) | G9: Vytvořit motivační systém, což zajištím že prodejní parteři jsou ochotní se učastnit na školící program. | H9: Díky existujícímu školícímu systému (S7) je možné rozšířit program i na partnery a standardizovat přístup k propagaci a prodeji produktů. | I9: do 2025.12 | K9: WT1
A10: ='5. TOWS matrix'!D24 -> WO2 | B10: ='5. TOWS matrix'!F24 -> W3,O3 | C10: Aktivní zapojení do formulace průmyslových standardů | D10: 9 | E10: Aktivně se účastnit oborového setkání a diskuse na úrovni ČR a EU o normách „přírodní“ a „bio“ kosmetiky | F10: Účastit se inimálně 5 oborových setkání. Prosadit přijetí minimálně dvou návrhů firmy do národních nebo evropských průmyslových standardů. | G10: Díky odborným znalostem a zkušenostem na českém trhu je tento cíl dosažitelný. | H10: zvýšit důvěryhodnost produktů a omezit nekalou konkurenci. | I10: do 2026.12
A11: ='5. TOWS matrix'!G15 -> ST3 | B11: ='5. TOWS matrix'!I15 -> S8,T7 | C11: ='5. TOWS matrix'!H15 -> Diferenciace produktů pomocí zaměstnanecké inovace | D11: 8 | E11: Zapojit zaměstnance do procesu inovace produktů prostřednictvím workshopů a týmových projektů zaměřených na ekologické hodnoty a jedinečnost produktů. | F11: Vyvinout 3 nové produkty nebo služby, které budou výsledkem návrhů zaměstnanců a zvýší tržby v daném segmentu o 10 %. | G11: Díky vysoké kvalitě zaměstnanců je zapojení zaměstnanců do inovací realistické a proveditelné | H11: Vytvořit ocenění a systém odměný za kreativitu na podporu innovací zaměstnanů. | I11: do 2026.12 | K11: SO2

Sheet List2
B1: =VLOOKUP(C1,'5. Faktory prostředí'!A$2:F$40,6,FALSE) -> S1 | C1: ='5. Faktory prostředí'!A3 -> Prospěch ze zdravotního povědomí
B2: =VLOOKUP(C2,'5. Faktory prostředí'!A$2:F$40,6,FALSE) -> S2 | C2: ='5. Faktory prostředí'!A4 -> Ekologicy založená firma
B3: =VLOOKUP(C3,'5. Faktory prostředí'!A$2:F$40,6,FALSE) -> S3 | C3: ='5. Faktory prostředí'!A5 -> Schopnost rychlé reakce na legislativu
B4: =VLOOKUP(C4,'5. Faktory prostředí'!A$2:F$40,6,FALSE) -> T1 | C4: ='5. Faktory prostředí'!A6 -> Přísné pravidla o UR
B5: =VLOOKUP(C5,'5. Faktory prostředí'!A$2:F$40,6,FALSE) -> S4 | C5: ='5. Faktory prostředí'!A7 -> Jednotným marketingovým přístupem lze přílákat nové zákaznky.
B6: =VLOOKUP(C6,'5. Faktory prostředí'!A$2:F$40,6,FALSE) -> T2 | C6: ='5. Faktory prostředí'!A8 -> Překážky pro vstup globalizace
B7: =VLOOKUP(C7,'5. Faktory prostředí'!A$2:F$40,6,FALSE) -> T3 | C7: ='5. Faktory prostředí'!A9 -> Konkurence ze strany malých firem
B8: =VLOOKUP(C8,'5. Faktory prostředí'!A$2:F$40,6,FALSE) -> T4 | C8: ='5. Faktory prostředí'!A10 -> Konkurence z innovace mezinárodních velých firem
B9: =VLOOKUP(C9,'5. Faktory prostředí'!A$2:F$40,6,FALSE) -> T5 | C9: ='5. Faktory prostředí'!A11 -> Existují silní konkurenti s větším počtem prodejen
B10: =VLOOKUP(C10,'5. Faktory prostředí'!A$2:F$40,6,FALSE) -> S5 | C10: ='5. Faktory prostředí'!A12 -> Ryzí a kvalitnější produkty
B11: =VLOOKUP(C11,'5. Faktory prostředí'!A$2:F$40,6,FALSE) -> O1 | C11: ='5. Faktory prostředí'!A13 -> Nové velké vstupující nedokážou vstoupit rychle
B12: =VLOOKUP(C12,'5. Faktory prostředí'!A$2:F$40,6,FALSE) -> T6 | C12: ='5. Faktory prostředí'!A14 -> Rostoucí atraktivita odvětví přiláká nové hráče
... B38: =VLOOKUP(C38,'5. Faktory prostředí'!A$2:F$40,6,FALSE) -> #N/A | C38: ='5. Faktory prostředí'!A40 -> 0
B39: =VLOOKUP(C39,'5. Faktory prostředí'!A$2:F$40,6,FALSE) -> #N/A | C39: T9
B40: =VLOOKUP(C40,'5. Faktory prostředí'!A$2:F$40,6,FALSE) -> #N/A | C40: T10

Sheet List1
A1: 1 | E1: 0
A2: 2 | E2: 0.5
A3: 3 | E3: 1
A4: 4

Sheet 6. Formulace strategie
A1: FORMULACE CÍLŮ A STRATEGIE K NIM VEDOUCÍ, IMPLEMENTACE STRATEGIE | B1: Počet znaků | F1: Body celkem
A2: Cílem této části semestrální práce je formulovat cíle organizace na základě výstupů SWOT analýzy a NOVOU strategii organizace na všech třech úrovních spolu s kroky implementace této strategie. | B2: Napsaných | C2: =C5+C8+C11+C14+C16+C18 -> 5962 | D2: Zbývá do maxima | E2: =-C2+10000 -> 4038 | F2: =C3+C6+C9+C12+C15+C17+C19 -> 0
A3: Pomocí segmentačních hledisek (demografické, geografické, psychografické a behaviorální) popište co nejpřesněji cílovou skupinu zákazníků a jejich požadavky. V případě, že operujete na B2B trhu, použijte segmentační kritéria pro tento trh. | B3: Počet bodů (max. 2)
A5: Cílová skupina: . Demografické hledisko: Zákazníci s vyšším vzděláním a příjmem, zaměřeni na zdravý životní styl a ekologické hodnoty. Věková skupina 25–65 let. . Geografické hledisko: Zaměření na městské oblasti, kde je vyšší koncentrace ekologicky smýšlejících zákazníků. Klíčové regiony jsou velká města a prémiové lokality. . Psychografické hledisko: Zákazníci jsou ochotni investovat do ekologicky certifikovaných produktů a dbají na image značky spojené s přírodními hodnotami. . Behaviorální hledisko: Ochota vyhledávat nové ekologické produkty, aktivní zapojení do diskuzí na téma zdravého životního stylu a ekologické odpovědnosti. Požadavky cílové skupiny: . Prémiové a ekologické produkty. . Transparentnost ve výrobě (např. bio certifikace). . Kvalitní zákaznický servis a snadná dostupnost (e-shop, kamenné prodejny). | B5: Znaky | C5: =LEN(A5) -> 831
A6: Na základě přechozích informací formulujte strategii na korporátní a business úrovni, propojte je cíli definovanými z TOWS matice. | B6: Počet bodů (max. 4)
A7: Cíle a strategie musí být formulovány tak, aby zde byla jasná provázanost s prostředím organizace, strategií na korporátní a business úrovni (typologie dle M. E. Portera).
A8: Korporátní strategie: Rozšířit vliv firmy na prémiovém trhu díky spolupráci s hotely, wellness centry a expanzi do nových regionů (SO1, SO4, WO1 z TOWS matice​). Aktivní zapojení do tvorby průmyslových standardů, které posílí důvěryhodnost a ochrání trh před nekalou konkurencí (WO2​) Business strategie (dle Portera): Diferenciační strategie – zaměření na jedinečnost produktů a ekologické hodnoty (ST3, ST1​). Fokus na prémiové segmenty – vývoj luxusních produktů a rozšíření značky prostřednictvím cíleného marketingu (SO3). | B8: Znaky | C8: =LEN(A8) -> 528
A9: Co je podstatou konkurenční výhody, jaké klíčové schopnosti bude využívat vaše organizace pro dosažení zvolené strategie. Kde v hodnotovém řetězci dochází k tvorbě konkurenční výhody? | B9: Počet bodů (max. 3)
A10: V rámci hodnotového řetězce porovnejte v každé jeho části náklady a přidanou hodnotu. Identifikujte, kde chcete tvořit základ konkurenční výhody, respektive, které procesy mají pro její tvoření největší význam.
A11: Podstata konkurenční výhody: . Prémiová kvalita a ekologické certifikace. . Rychlá adaptace na legislativní změny. . Kvalitní zákaznická péče: Díky důrazu na odborně vyškolené zaměstnance se organizace odlišuje od konkurence. . Školicí systém: Jedinečný systém školení (ST2, SO7​), který podporuje znalosti o ekologických hodnotách produktů a zároveň standardizuje přístup partnerů a zaměstnanců. Hodnotový řetězec: Primární aktivity: . Marketing a prodej: Podpora značky skrze cílené marketingové kampaně zaměřené na ekologické a přírodní hodnoty (ST1) a zlepšení brand awareness. . Servis: Implementace školení pro partnery a zaměstnance zlepšující zákaznický servis. Podpůrné aktivity: . Infrastruktura firmy: Posílení školícího systému, který zajišťuje jednotnou kvalitu služeb v celém dodavatelském řetězci. . Lidské zdroje: Investice do kvality zaměstnanců, kteří jsou školeni pro poskytování špičkové zákaznické péče. | B11: Znaky | C11: =LEN(A11) -> 925
A12: Jak tvorba je konkurenční výhody propojena se strategií formulovanou na business úrovni? | B12: Počet bodů (max. 3)
A13: Diskutujte výsledky hodnotového řetězce spolu se zvolenou strategií (nízkonákladová, diferenciační, fokálně nízkonákladová, fokálně diferenciační, hybridní či stuck-in-the middle). Diskutujte vámi formulovanou strategii, nikoliv současnou strategii vybrané organizace.
A14: . Diferenciační strategie: Zaměření na kvalitní zákaznický servis a školení podporuje dlouhodobé vztahy se zákazníky a partnery, což přispívá k budování image značky jako lídra v prémiovém a ekologickém segmentu. . Školící systém zajišťuje, že všechny prodejní kanály poskytují konzistentní a vysokou úroveň služeb, což je klíčové pro diferenciaci na trhu. Ty podporují expanzi a odlišení od konkurence. | B14: Znaky | C14: =LEN(A14) -> 405
A15: Diskutujte rozložení operativní aktivit (vývoj produktu, marketing, materiály, produkce, prodej, servis) vzhledem ke zvolenému zaměření na funkční úrovni tvorby strategie (zaměření na inovace, kvalitu, zákazníka či efektivnost) v souvislosti s konkurenční výhodou u vámi nově formulované strategie. | B15: Počet bodů (max. 4)
A16: Zaměření na inovace: -Materiály a produkce: Investice do ekologického balení a optimalizace dodavatelského řetězce pro podporu prémiových produktů. -Vývoj produktu: Zaměření na inovace s důrazem na ekologické hodnoty a využití návrhů od zaměstnanců. Např. zaměstnanecké workshopy vedoucí k vývoji nových produktů. Zaměření na kvalitu: -Vývoj produktu: Investice do vývoje produktů, které využívají přírodní suroviny a reagují na nové trendy (např. zvýšený zájem o imunitu a zdraví po covidu)​ -Marketing: Budování povědomí o vysoké kvalitě produktů prostřednictvím komunikace s důrazem na certifikace a ekologickou odpovědnost Zaměření na zákazníka: Servis: Klíčová oblast, zahrnující personalizovanou zákaznickou podporu a posílení poprodejní péče a vzdělávání partnerů (např. školící programy). -Prodej: Rozšíření sítě kamenných prodejen a zlepšení dostupnosti prémiových produktů zárovň se zaměřením na zákaznický zážitek. -Marketing: Kampaně, které zdůrazňují kvalitní producty s služeb a odborné znalosti zaměstnanců. Zaměření na efektivnost: -Servis: školení zaměstnanců se zaměřené na zvýšení produktivity a efektivity zákaznické podpory. -Prodej: rychleji reakce na objednávky a servisní požadavky zlepší zákaznickou zkušenost. | B16: Znaky | C16: =LEN(A16) -> 1240
A17: Popište kroky implementace vámi formulované strategie pomocí struktury, kultury a kontroly a jejich konkrétního nastavení. Představte, jak se toto nastavení bude projevovat v operativních aktivitách (přeměna vstupů na výstupy) s cílem naplnění funkční a business strategie? | B17: Počet bodů (max. 4)
A18: Struktura: Vytvoření týmu pro prémiový segment: Tento tým taky bude klíčovou příležitostí pro interní zaměstnance, aby si rozvíjeli kariéru. Vytvoření týmu umožní talentovaným jednotlivcům postoupit na vyšší pozice, což motivuje zaměstnance k většímu zapojení. Motivační systém: Firma zavede bonusový systém, který bude zaměřen na obchodní zástupce i partnery. Bonusy budou odměňovat za dosažení konkrétních cílů, jako je zvýšení prodeje, získání nových partnerů. Kultura: Zaměření na servis i výsledky: Kulturní hodnoty firmy se posunou směrem k výstupům, jako je kvalita zákaznického servisu, dosažení prodejních cílů a efektivní odbyt. Sdílení znalostí: Firma vytvoří prostředí, které podporuje sdílení znalostí mezi zaměstnanci. To zahrnuje například interní workshopy, mentoring od zkušenějších kolegů a podporu inovací. Podpora od nadřízených: Klíčovou součástí kultury bude aktivní zapojení manažerů, kteří budou zaměstnancům poskytovat zpětnou vazbu, vedení a motivaci. Kontrola: Ukazatele výkonu: Kromě měření růstu tržeb, počtu nových partnerů a efektivity marketingu budou ukazatele zahrnovat také: Podíl nespokojených zákazníků: Měření prostřednictvím zákaznických recenzí, stížností a dotazníků. Vrácené produkty: Analýza důvodů pro vracení zboží a jejich minimalizace skrze zlepšení kvality produktů a komunikace. Projev v operativních aktivitách Vývoj a inovace: Firma zvýší investice do vývoje ekologických produktů a zavede nové produkty odpovídající požadavkům prémiového trhu. Školení: Školící programy se rozšíří nejen na zaměstnance, ale také na partnery. Tím se zajistí, že zákazníci budou mít vždy kvalitní a konzistentní servis. Marketing: Více investic do cílených kampaní zvýší povědomí o značce a přiláká nové zákazníky. Prodej: Nové kamenné prodejny budou optimalizovány pro interakci se zákazníky, což posílí loajalitu a přímý prodej. Servis: Personalizovaná péče o zákazníky se stane prioritou. Prodejci a partneři budou lépe proškoleni v řešení problémů a budování dlouhodobých vztahů se zákazníky. | B18: Znaky | C18: =LEN(A18) -> 2033

Sheet 2.Analýza hodnotové křivky
C2: cena | D2: kvalita,čistota,Certifikáty | E2: dostupnost | F2: důvěryhodnost | G2: účinky | H2: členství a benefity | I2: specifika aromy | J2: wide selections | K2: knowledageable staff | L2: brand awareness | M2: balení
B3: Konkurence | C3: 4 | D3: 5 | E3: 2 | F3: 3 | G3: 5 | H3: 3 | I3: 3 | J3: 5 | K3: 5 | L3: 5 | M3: 5
B4: Požadavek zákaznika | C4: 1 | D4: 5 | E4: 4 | F4: 5 | G4: 4 | H4: 4 | I4: 4 | J4: 4 | K4: 5 | L4: 4 | M4: 4
B5: modrý oceán | C5: 3 | D5: 4 | E5: 5 | F5: 4 | G5: 4 | H5: 5 | I5: 5 | J5: 3 | K5: 5 | L5: 4 | M5: 3

Sheet 3. pracovní list
A1: Řízení lidských zdrojů a školení personálu
A2: Řízení dodovatleů/Řízení kvality
A3: výzkum a vývoj nových vyrobků | F3: margin
A4: obstaravatelská čínnost
A5: Řízení vstupních operací | B5: Výroba a provoz | C5: Řízení výstupních operací | D5: Marketing a odbyt | E5: popordenjní service produktu | F5: margin
D6: Vytvořte kurzy/service postupy | E6: nabízí osobí service/kurzy
F8: zdroje | G8: Hodnotný | H8: Vzácný | I8: Obtížně imitovatelný | J8: Uspořádané prostředí | K8: Konkurenční efekt | L8: Ekonom. Dopad
F9: Certificace, výzkum a vývoj | G9: Ano | H9: Ne | K9: Konkurenčnírovnost | L9: 0
F10: přírodní kosmeticky založené na aromaterapii | G10: Ano | H10: Ano | I10: Ne | J10: Ne | K10: Dočasná výhoda | L10: dočasná++
F11: vzděláváním a osvětovou činností | G11: Ano | H11: Ano | I11: Ne | J11: Ne | K11: Dočasná výhoda | L11: dočasná++

Sheet 4.Power-interest Matrix
D2: Power-interest Matrix
B3: vysoký | C3: =C4+1 -> 10 | J3: Celebrity branding [2] | M3: Vlastnici
C4: =C5+1 -> 9 | F4: Dodavatelé | H4: Obchodní zástupci
C5: =C6+1 -> 8 | F5: Zákazníci | H5: Zaměstnanci | J5: Partnerské prodejny
C6: =C7+1 -> 7
B7: Zájem | C7: =C8+1 -> 6
C8: =C9+1 -> 5
C9: =C10+1 -> 4
C10: =C11+1 -> 3 | G10: Certifikační organy | J10: Sdružení obrany spotřebitelů
C11: =C12+1 -> 2 | D11: Sousedi centru aromaterapie
B12: nízký | C12: 1 | J12: ČOI [1]
D13: 1 | E13: =D13+1 -> 2 | F13: =E13+1 -> 3 | G13: =F13+1 -> 4 | H13: =G13+1 -> 5 | I13: =H13+1 -> 6 | J13: =I13+1 -> 7 | K13: =J13+1 -> 8 | L13: =K13+1 -> 9 | M13: =L13+1 -> 10
D14: nízká | H14: Síla | M14: vysoká
D15: 1.ČOI: Česká obchodní inspekce
D16: 2.Andrea Růžičková je první ambasadorkou české přírodní kosmetiky Nobilis Tilia.

Sheet 4.Členění inovací
C2: Členění inovací
A3: Systém
D4: Nová verze výrobku | F4: Nová generace | H4: Revoluce v odvětví
B5: úrovň | D5: . nová vůňe pro nové segmenty. Např. do lázně pro seniory. | L5: {=LEN(A2:I9)} -> 0 | M5: 0 | N5: 15 | O5: 0 | P5: 0 | Q5: 0 | R5: 0 | S5: 0 | T5: 0
D6: Zlepšení Komponet | F6: Nová Komponety | H6: Nová Koncepce Komponety | K6: =SUM(_xlfn.ANCHORARRAY(L5)) -> 456 | L6: 6 | M6: 0 | N6: 0 | O6: 0 | P6: 0 | Q6: 0 | R6: 0 | S6: 0 | T6: 0
A7: Dílčí části | D7: . Zvyšit počet bio-productů . Snišit počet výužití plasticé obaly. | F7: . Na základě zákazníkové database výtvoří nový systém členství. . Nabízí nový kurzy. Např. certificační kurzy pro amromaterapeutika | L7: 0 | M7: 0 | N7: 0 | O7: 18 | P7: 0 | Q7: 13 | R7: 0 | S7: 18 | T7: 0
C8: Inkrementní inovace | E8: Hloubka | H8: Radikání inovace | L8: 0 | M8: 5 | N8: 0 | O8: 59 | P8: 0 | Q8: 0 | R8: 0 | S8: 0 | T8: 0
C9: podnik | E9: Dosah | I9: Svět | L9: 0 | M9: 0 | N9: 0 | O9: 18 | P9: 0 | Q9: 14 | R9: 0 | S9: 23 | T9: 0
L10: 11 | M10: 0 | N10: 0 | O10: 66 | P10: 0 | Q10: 132 | R10: 0 | S10: 0 | T10: 0
L11: 0 | M11: 0 | N11: 19 | O11: 0 | P11: 7 | Q11: 0 | R11: 0 | S11: 16 | T11: 0
L12: 0 | M12: 0 | N12: 6 | O12: 0 | P12: 6 | Q12: 0 | R12: 0 | S12: 0 | T12: 4
L13: =SUM(L5:L12) -> 17 | M13: =SUM(M5:M12) -> 5 | N13: =SUM(N5:N12) -> 40 | O13: =SUM(O5:O12) -> 161 | P13: =SUM(P5:P12) -> 13 | Q13: =SUM(Q5:Q12) -> 159 | R13: =SUM(R5:R12) -> 0 | S13: =SUM(S5:S12) -> 57 | T13: =SUM(T5:T12) -> 4

Sheet Sheet1
A1: Poznámky k faktorům | C1: Zařazení
A2: Název faktoru | B2: Komentář - MAP přístup (Monitoring, Analysis, Prediction) | C2: Slabá stránka | D2: Kód | F2: kód | L2: Silná stránka
A3: Prospěch ze zdravotního povědomí | B3: Po covidu se zvýšil zájem o výrobky, které posilují imunitu a podporují zdraví. Aromaterapeutické produkty se tak těší zvýšené poptávce. Naše firma v tom odvětví a vyrobkoý sortment má dobrou pověst. Firma tak očekává lepší příjem než v minulosti. | C3: Silná stránka | D3: O | E3: 1 | F3: S1 | L3: Slabá stránka
A4: Ekologicy založená firma | B4: Firma má dlouhodobou tradici a dbá na to, aby podnikala ekologicky. To přispívá k pozitivnímu vnímání značky, což může zvyšovat loajalitu zákazníků. Umožní to rozšíření trhu díky preferenci ekologicky orientovaných zákazníků. | C4: Silná stránka | D4: O | E4: 2 | F4: S2 | L4: Příležitost
A5: Schopnost rychlé reakce na legislativu | B5: Vlastní schopnost rychlé reakce na měnící se legislativu o udržitelném rozvoji. Umožňuje minimalizovat právní a finanční rizika. Firma může podpory využít EU v rámci dotačních programů na udržitelný rozvoj. | C5: Silná stránka | D5: O | E5: 2 | F5: S3 | L5: Příležitost
A6: Přísné pravidla o UR | B6: Balení výrobků a materiálů v obalech je pečlivě sledováno legistlativou EU ohledně SDGs. Firma čelí čím dál přísnějším požadavkům ekologických pravidel. Adaptace na pravidla může být nákladná. | C6: Hrozba | D6: T | E6: 1 | F6: T1 | L6: Hrozba
